Internal Server Error: /api/v1/admin/plan
Traceback (most recent call last):
  File "/home/ramabitc/virtualenv/ramabit/3.7/lib/python3.7/site-packages/django/core/handlers/exception.py", line 47, in inner
    response = get_response(request)
  File "/home/ramabitc/virtualenv/ramabit/3.7/lib/python3.7/site-packages/django/core/handlers/base.py", line 181, in _get_response
    response = wrapped_callback(request, *callback_args, **callback_kwargs)
  File "/home/ramabitc/virtualenv/ramabit/3.7/lib/python3.7/site-packages/django/views/decorators/csrf.py", line 54, in wrapped_view
    return view_func(*args, **kwargs)
  File "/home/ramabitc/virtualenv/ramabit/3.7/lib/python3.7/site-packages/django/views/generic/base.py", line 70, in view
    return self.dispatch(request, *args, **kwargs)
  File "/home/ramabitc/virtualenv/ramabit/3.7/lib/python3.7/site-packages/rest_framework/views.py", line 509, in dispatch
    response = self.handle_exception(exc)
  File "/home/ramabitc/virtualenv/ramabit/3.7/lib/python3.7/site-packages/rest_framework/views.py", line 469, in handle_exception
    self.raise_uncaught_exception(exc)
  File "/home/ramabitc/virtualenv/ramabit/3.7/lib/python3.7/site-packages/rest_framework/views.py", line 480, in raise_uncaught_exception
    raise exc
  File "/home/ramabitc/virtualenv/ramabit/3.7/lib/python3.7/site-packages/rest_framework/views.py", line 506, in dispatch
    response = handler(request, *args, **kwargs)
TypeError: put() missing 1 required positional argument: 'id'
Internal Server Error: /api/admin/auctions/transactions/add/
Traceback (most recent call last):
  File "/home/ramabitc/virtualenv/ramabit/3.7/lib/python3.7/site-packages/django/db/backends/utils.py", line 84, in _execute
    return self.cursor.execute(sql, params)
psycopg2.errors.NotNullViolation: null value in column "id" violates not-null constraint
DETAIL:  Failing row contains (null, 2024-05-25, 1, 1, 2, 1).


The above exception was the direct cause of the following exception:

Traceback (most recent call last):
  File "/home/ramabitc/virtualenv/ramabit/3.7/lib/python3.7/site-packages/django/core/handlers/exception.py", line 47, in inner
    response = get_response(request)
  File "/home/ramabitc/virtualenv/ramabit/3.7/lib/python3.7/site-packages/django/core/handlers/base.py", line 181, in _get_response
    response = wrapped_callback(request, *callback_args, **callback_kwargs)
  File "/home/ramabitc/virtualenv/ramabit/3.7/lib/python3.7/site-packages/django/contrib/admin/options.py", line 616, in wrapper
    return self.admin_site.admin_view(view)(*args, **kwargs)
  File "/home/ramabitc/virtualenv/ramabit/3.7/lib/python3.7/site-packages/django/utils/decorators.py", line 130, in _wrapped_view
    response = view_func(request, *args, **kwargs)
  File "/home/ramabitc/virtualenv/ramabit/3.7/lib/python3.7/site-packages/django/views/decorators/cache.py", line 44, in _wrapped_view_func
    response = view_func(request, *args, **kwargs)
  File "/home/ramabitc/virtualenv/ramabit/3.7/lib/python3.7/site-packages/django/contrib/admin/sites.py", line 232, in inner
    return view(request, *args, **kwargs)
  File "/home/ramabitc/virtualenv/ramabit/3.7/lib/python3.7/site-packages/django/contrib/admin/options.py", line 1657, in add_view
    return self.changeform_view(request, None, form_url, extra_context)
  File "/home/ramabitc/virtualenv/ramabit/3.7/lib/python3.7/site-packages/django/utils/decorators.py", line 43, in _wrapper
    return bound_method(*args, **kwargs)
  File "/home/ramabitc/virtualenv/ramabit/3.7/lib/python3.7/site-packages/django/utils/decorators.py", line 130, in _wrapped_view
    response = view_func(request, *args, **kwargs)
  File "/home/ramabitc/virtualenv/ramabit/3.7/lib/python3.7/site-packages/django/contrib/admin/options.py", line 1540, in changeform_view
    return self._changeform_view(request, object_id, form_url, extra_context)
  File "/home/ramabitc/virtualenv/ramabit/3.7/lib/python3.7/site-packages/django/contrib/admin/options.py", line 1586, in _changeform_view
    self.save_model(request, new_object, form, not add)
  File "/home/ramabitc/virtualenv/ramabit/3.7/lib/python3.7/site-packages/django/contrib/admin/options.py", line 1099, in save_model
    obj.save()
  File "/home/ramabitc/virtualenv/ramabit/3.7/lib/python3.7/site-packages/django/db/models/base.py", line 740, in save
    force_update=force_update, update_fields=update_fields)
  File "/home/ramabitc/virtualenv/ramabit/3.7/lib/python3.7/site-packages/django/db/models/base.py", line 778, in save_base
    force_update, using, update_fields,
  File "/home/ramabitc/virtualenv/ramabit/3.7/lib/python3.7/site-packages/django/db/models/base.py", line 881, in _save_table
    results = self._do_insert(cls._base_manager, using, fields, returning_fields, raw)
  File "/home/ramabitc/virtualenv/ramabit/3.7/lib/python3.7/site-packages/django/db/models/base.py", line 921, in _do_insert
    using=using, raw=raw,
  File "/home/ramabitc/virtualenv/ramabit/3.7/lib/python3.7/site-packages/django/db/models/manager.py", line 85, in manager_method
    return getattr(self.get_queryset(), name)(*args, **kwargs)
  File "/home/ramabitc/virtualenv/ramabit/3.7/lib/python3.7/site-packages/django/db/models/query.py", line 1270, in _insert
    return query.get_compiler(using=using).execute_sql(returning_fields)
  File "/home/ramabitc/virtualenv/ramabit/3.7/lib/python3.7/site-packages/django/db/models/sql/compiler.py", line 1416, in execute_sql
    cursor.execute(sql, params)
  File "/home/ramabitc/virtualenv/ramabit/3.7/lib/python3.7/site-packages/django/db/backends/utils.py", line 98, in execute
    return super().execute(sql, params)
  File "/home/ramabitc/virtualenv/ramabit/3.7/lib/python3.7/site-packages/django/db/backends/utils.py", line 66, in execute
    return self._execute_with_wrappers(sql, params, many=False, executor=self._execute)
  File "/home/ramabitc/virtualenv/ramabit/3.7/lib/python3.7/site-packages/django/db/backends/utils.py", line 75, in _execute_with_wrappers
    return executor(sql, params, many, context)
  File "/home/ramabitc/virtualenv/ramabit/3.7/lib/python3.7/site-packages/django/db/backends/utils.py", line 84, in _execute
    return self.cursor.execute(sql, params)
  File "/home/ramabitc/virtualenv/ramabit/3.7/lib/python3.7/site-packages/django/db/utils.py", line 90, in __exit__
    raise dj_exc_value.with_traceback(traceback) from exc_value
  File "/home/ramabitc/virtualenv/ramabit/3.7/lib/python3.7/site-packages/django/db/backends/utils.py", line 84, in _execute
    return self.cursor.execute(sql, params)
django.db.utils.IntegrityError: null value in column "id" violates not-null constraint
DETAIL:  Failing row contains (null, 2024-05-25, 1, 1, 2, 1).

Internal Server Error: /api/admin/auctions/transactions/add/
Traceback (most recent call last):
  File "/home/ramabitc/virtualenv/ramabit/3.7/lib/python3.7/site-packages/django/db/backends/utils.py", line 84, in _execute
    return self.cursor.execute(sql, params)
psycopg2.errors.StringDataRightTruncation: value too long for type character varying(10)


The above exception was the direct cause of the following exception:

Traceback (most recent call last):
  File "/home/ramabitc/virtualenv/ramabit/3.7/lib/python3.7/site-packages/django/core/handlers/exception.py", line 47, in inner
    response = get_response(request)
  File "/home/ramabitc/virtualenv/ramabit/3.7/lib/python3.7/site-packages/django/core/handlers/base.py", line 181, in _get_response
    response = wrapped_callback(request, *callback_args, **callback_kwargs)
  File "/home/ramabitc/virtualenv/ramabit/3.7/lib/python3.7/site-packages/django/contrib/admin/options.py", line 616, in wrapper
    return self.admin_site.admin_view(view)(*args, **kwargs)
  File "/home/ramabitc/virtualenv/ramabit/3.7/lib/python3.7/site-packages/django/utils/decorators.py", line 130, in _wrapped_view
    response = view_func(request, *args, **kwargs)
  File "/home/ramabitc/virtualenv/ramabit/3.7/lib/python3.7/site-packages/django/views/decorators/cache.py", line 44, in _wrapped_view_func
    response = view_func(request, *args, **kwargs)
  File "/home/ramabitc/virtualenv/ramabit/3.7/lib/python3.7/site-packages/django/contrib/admin/sites.py", line 232, in inner
    return view(request, *args, **kwargs)
  File "/home/ramabitc/virtualenv/ramabit/3.7/lib/python3.7/site-packages/django/contrib/admin/options.py", line 1657, in add_view
    return self.changeform_view(request, None, form_url, extra_context)
  File "/home/ramabitc/virtualenv/ramabit/3.7/lib/python3.7/site-packages/django/utils/decorators.py", line 43, in _wrapper
    return bound_method(*args, **kwargs)
  File "/home/ramabitc/virtualenv/ramabit/3.7/lib/python3.7/site-packages/django/utils/decorators.py", line 130, in _wrapped_view
    response = view_func(request, *args, **kwargs)
  File "/home/ramabitc/virtualenv/ramabit/3.7/lib/python3.7/site-packages/django/contrib/admin/options.py", line 1540, in changeform_view
    return self._changeform_view(request, object_id, form_url, extra_context)
  File "/home/ramabitc/virtualenv/ramabit/3.7/lib/python3.7/site-packages/django/contrib/admin/options.py", line 1586, in _changeform_view
    self.save_model(request, new_object, form, not add)
  File "/home/ramabitc/virtualenv/ramabit/3.7/lib/python3.7/site-packages/django/contrib/admin/options.py", line 1099, in save_model
    obj.save()
  File "/home/ramabitc/virtualenv/ramabit/3.7/lib/python3.7/site-packages/django/db/models/base.py", line 740, in save
    force_update=force_update, update_fields=update_fields)
  File "/home/ramabitc/virtualenv/ramabit/3.7/lib/python3.7/site-packages/django/db/models/base.py", line 778, in save_base
    force_update, using, update_fields,
  File "/home/ramabitc/virtualenv/ramabit/3.7/lib/python3.7/site-packages/django/db/models/base.py", line 881, in _save_table
    results = self._do_insert(cls._base_manager, using, fields, returning_fields, raw)
  File "/home/ramabitc/virtualenv/ramabit/3.7/lib/python3.7/site-packages/django/db/models/base.py", line 921, in _do_insert
    using=using, raw=raw,
  File "/home/ramabitc/virtualenv/ramabit/3.7/lib/python3.7/site-packages/django/db/models/manager.py", line 85, in manager_method
    return getattr(self.get_queryset(), name)(*args, **kwargs)
  File "/home/ramabitc/virtualenv/ramabit/3.7/lib/python3.7/site-packages/django/db/models/query.py", line 1270, in _insert
    return query.get_compiler(using=using).execute_sql(returning_fields)
  File "/home/ramabitc/virtualenv/ramabit/3.7/lib/python3.7/site-packages/django/db/models/sql/compiler.py", line 1416, in execute_sql
    cursor.execute(sql, params)
  File "/home/ramabitc/virtualenv/ramabit/3.7/lib/python3.7/site-packages/django/db/backends/utils.py", line 98, in execute
    return super().execute(sql, params)
  File "/home/ramabitc/virtualenv/ramabit/3.7/lib/python3.7/site-packages/django/db/backends/utils.py", line 66, in execute
    return self._execute_with_wrappers(sql, params, many=False, executor=self._execute)
  File "/home/ramabitc/virtualenv/ramabit/3.7/lib/python3.7/site-packages/django/db/backends/utils.py", line 75, in _execute_with_wrappers
    return executor(sql, params, many, context)
  File "/home/ramabitc/virtualenv/ramabit/3.7/lib/python3.7/site-packages/django/db/backends/utils.py", line 84, in _execute
    return self.cursor.execute(sql, params)
  File "/home/ramabitc/virtualenv/ramabit/3.7/lib/python3.7/site-packages/django/db/utils.py", line 90, in __exit__
    raise dj_exc_value.with_traceback(traceback) from exc_value
  File "/home/ramabitc/virtualenv/ramabit/3.7/lib/python3.7/site-packages/django/db/backends/utils.py", line 84, in _execute
    return self.cursor.execute(sql, params)
django.db.utils.DataError: value too long for type character varying(10)

Internal Server Error: /api/admin/auctions/transactions/add/
Traceback (most recent call last):
  File "/home/ramabitc/virtualenv/ramabit/3.7/lib/python3.7/site-packages/django/db/backends/utils.py", line 84, in _execute
    return self.cursor.execute(sql, params)
psycopg2.errors.StringDataRightTruncation: value too long for type character varying(10)


The above exception was the direct cause of the following exception:

Traceback (most recent call last):
  File "/home/ramabitc/virtualenv/ramabit/3.7/lib/python3.7/site-packages/django/core/handlers/exception.py", line 47, in inner
    response = get_response(request)
  File "/home/ramabitc/virtualenv/ramabit/3.7/lib/python3.7/site-packages/django/core/handlers/base.py", line 181, in _get_response
    response = wrapped_callback(request, *callback_args, **callback_kwargs)
  File "/home/ramabitc/virtualenv/ramabit/3.7/lib/python3.7/site-packages/django/contrib/admin/options.py", line 616, in wrapper
    return self.admin_site.admin_view(view)(*args, **kwargs)
  File "/home/ramabitc/virtualenv/ramabit/3.7/lib/python3.7/site-packages/django/utils/decorators.py", line 130, in _wrapped_view
    response = view_func(request, *args, **kwargs)
  File "/home/ramabitc/virtualenv/ramabit/3.7/lib/python3.7/site-packages/django/views/decorators/cache.py", line 44, in _wrapped_view_func
    response = view_func(request, *args, **kwargs)
  File "/home/ramabitc/virtualenv/ramabit/3.7/lib/python3.7/site-packages/django/contrib/admin/sites.py", line 232, in inner
    return view(request, *args, **kwargs)
  File "/home/ramabitc/virtualenv/ramabit/3.7/lib/python3.7/site-packages/django/contrib/admin/options.py", line 1657, in add_view
    return self.changeform_view(request, None, form_url, extra_context)
  File "/home/ramabitc/virtualenv/ramabit/3.7/lib/python3.7/site-packages/django/utils/decorators.py", line 43, in _wrapper
    return bound_method(*args, **kwargs)
  File "/home/ramabitc/virtualenv/ramabit/3.7/lib/python3.7/site-packages/django/utils/decorators.py", line 130, in _wrapped_view
    response = view_func(request, *args, **kwargs)
  File "/home/ramabitc/virtualenv/ramabit/3.7/lib/python3.7/site-packages/django/contrib/admin/options.py", line 1540, in changeform_view
    return self._changeform_view(request, object_id, form_url, extra_context)
  File "/home/ramabitc/virtualenv/ramabit/3.7/lib/python3.7/site-packages/django/contrib/admin/options.py", line 1586, in _changeform_view
    self.save_model(request, new_object, form, not add)
  File "/home/ramabitc/virtualenv/ramabit/3.7/lib/python3.7/site-packages/django/contrib/admin/options.py", line 1099, in save_model
    obj.save()
  File "/home/ramabitc/virtualenv/ramabit/3.7/lib/python3.7/site-packages/django/db/models/base.py", line 740, in save
    force_update=force_update, update_fields=update_fields)
  File "/home/ramabitc/virtualenv/ramabit/3.7/lib/python3.7/site-packages/django/db/models/base.py", line 778, in save_base
    force_update, using, update_fields,
  File "/home/ramabitc/virtualenv/ramabit/3.7/lib/python3.7/site-packages/django/db/models/base.py", line 881, in _save_table
    results = self._do_insert(cls._base_manager, using, fields, returning_fields, raw)
  File "/home/ramabitc/virtualenv/ramabit/3.7/lib/python3.7/site-packages/django/db/models/base.py", line 921, in _do_insert
    using=using, raw=raw,
  File "/home/ramabitc/virtualenv/ramabit/3.7/lib/python3.7/site-packages/django/db/models/manager.py", line 85, in manager_method
    return getattr(self.get_queryset(), name)(*args, **kwargs)
  File "/home/ramabitc/virtualenv/ramabit/3.7/lib/python3.7/site-packages/django/db/models/query.py", line 1270, in _insert
    return query.get_compiler(using=using).execute_sql(returning_fields)
  File "/home/ramabitc/virtualenv/ramabit/3.7/lib/python3.7/site-packages/django/db/models/sql/compiler.py", line 1416, in execute_sql
    cursor.execute(sql, params)
  File "/home/ramabitc/virtualenv/ramabit/3.7/lib/python3.7/site-packages/django/db/backends/utils.py", line 98, in execute
    return super().execute(sql, params)
  File "/home/ramabitc/virtualenv/ramabit/3.7/lib/python3.7/site-packages/django/db/backends/utils.py", line 66, in execute
    return self._execute_with_wrappers(sql, params, many=False, executor=self._execute)
  File "/home/ramabitc/virtualenv/ramabit/3.7/lib/python3.7/site-packages/django/db/backends/utils.py", line 75, in _execute_with_wrappers
    return executor(sql, params, many, context)
  File "/home/ramabitc/virtualenv/ramabit/3.7/lib/python3.7/site-packages/django/db/backends/utils.py", line 84, in _execute
    return self.cursor.execute(sql, params)
  File "/home/ramabitc/virtualenv/ramabit/3.7/lib/python3.7/site-packages/django/db/utils.py", line 90, in __exit__
    raise dj_exc_value.with_traceback(traceback) from exc_value
  File "/home/ramabitc/virtualenv/ramabit/3.7/lib/python3.7/site-packages/django/db/backends/utils.py", line 84, in _execute
    return self.cursor.execute(sql, params)
django.db.utils.DataError: value too long for type character varying(10)

Internal Server Error: /api/v1/admin/miner
Traceback (most recent call last):
  File "/home/ramabitc/virtualenv/ramabit/3.7/lib/python3.7/site-packages/django/core/handlers/exception.py", line 47, in inner
    response = get_response(request)
  File "/home/ramabitc/virtualenv/ramabit/3.7/lib/python3.7/site-packages/django/core/handlers/base.py", line 181, in _get_response
    response = wrapped_callback(request, *callback_args, **callback_kwargs)
  File "/home/ramabitc/virtualenv/ramabit/3.7/lib/python3.7/site-packages/django/views/decorators/csrf.py", line 54, in wrapped_view
    return view_func(*args, **kwargs)
  File "/home/ramabitc/virtualenv/ramabit/3.7/lib/python3.7/site-packages/django/views/generic/base.py", line 70, in view
    return self.dispatch(request, *args, **kwargs)
  File "/home/ramabitc/virtualenv/ramabit/3.7/lib/python3.7/site-packages/rest_framework/views.py", line 509, in dispatch
    response = self.handle_exception(exc)
  File "/home/ramabitc/virtualenv/ramabit/3.7/lib/python3.7/site-packages/rest_framework/views.py", line 469, in handle_exception
    self.raise_uncaught_exception(exc)
  File "/home/ramabitc/virtualenv/ramabit/3.7/lib/python3.7/site-packages/rest_framework/views.py", line 480, in raise_uncaught_exception
    raise exc
  File "/home/ramabitc/virtualenv/ramabit/3.7/lib/python3.7/site-packages/rest_framework/views.py", line 506, in dispatch
    response = handler(request, *args, **kwargs)
  File "/home/ramabitc/ramabit/admin/views.py", line 699, in post
    profit = request.data['profit']
KeyError: 'profit'
Internal Server Error: /api/v1/admin/miner
Traceback (most recent call last):
  File "/home/ramabitc/virtualenv/ramabit/3.7/lib/python3.7/site-packages/django/core/handlers/exception.py", line 47, in inner
    response = get_response(request)
  File "/home/ramabitc/virtualenv/ramabit/3.7/lib/python3.7/site-packages/django/core/handlers/base.py", line 181, in _get_response
    response = wrapped_callback(request, *callback_args, **callback_kwargs)
  File "/home/ramabitc/virtualenv/ramabit/3.7/lib/python3.7/site-packages/django/views/decorators/csrf.py", line 54, in wrapped_view
    return view_func(*args, **kwargs)
  File "/home/ramabitc/virtualenv/ramabit/3.7/lib/python3.7/site-packages/django/views/generic/base.py", line 70, in view
    return self.dispatch(request, *args, **kwargs)
  File "/home/ramabitc/virtualenv/ramabit/3.7/lib/python3.7/site-packages/rest_framework/views.py", line 509, in dispatch
    response = self.handle_exception(exc)
  File "/home/ramabitc/virtualenv/ramabit/3.7/lib/python3.7/site-packages/rest_framework/views.py", line 469, in handle_exception
    self.raise_uncaught_exception(exc)
  File "/home/ramabitc/virtualenv/ramabit/3.7/lib/python3.7/site-packages/rest_framework/views.py", line 480, in raise_uncaught_exception
    raise exc
  File "/home/ramabitc/virtualenv/ramabit/3.7/lib/python3.7/site-packages/rest_framework/views.py", line 506, in dispatch
    response = handler(request, *args, **kwargs)
  File "/home/ramabitc/ramabit/admin/views.py", line 699, in post
    profit = request.data['profit']
KeyError: 'profit'
Internal Server Error: /api/v1/admin/miner/9
Traceback (most recent call last):
  File "/home/ramabitc/virtualenv/ramabit/3.7/lib/python3.7/site-packages/django/core/handlers/exception.py", line 47, in inner
    response = get_response(request)
  File "/home/ramabitc/virtualenv/ramabit/3.7/lib/python3.7/site-packages/django/utils/deprecation.py", line 116, in __call__
    response = self.process_request(request)
  File "/home/ramabitc/virtualenv/ramabit/3.7/lib/python3.7/site-packages/django/middleware/common.py", line 53, in process_request
    if self.should_redirect_with_slash(request):
  File "/home/ramabitc/virtualenv/ramabit/3.7/lib/python3.7/site-packages/django/middleware/common.py", line 70, in should_redirect_with_slash
    if not is_valid_path(request.path_info, urlconf):
  File "/home/ramabitc/virtualenv/ramabit/3.7/lib/python3.7/site-packages/django/urls/base.py", line 153, in is_valid_path
    return resolve(path, urlconf)
  File "/home/ramabitc/virtualenv/ramabit/3.7/lib/python3.7/site-packages/django/urls/base.py", line 24, in resolve
    return get_resolver(urlconf).resolve(path)
  File "/home/ramabitc/virtualenv/ramabit/3.7/lib/python3.7/site-packages/django/urls/resolvers.py", line 560, in resolve
    for pattern in self.url_patterns:
  File "/home/ramabitc/virtualenv/ramabit/3.7/lib/python3.7/site-packages/django/utils/functional.py", line 48, in __get__
    res = instance.__dict__[self.name] = self.func(instance)
  File "/home/ramabitc/virtualenv/ramabit/3.7/lib/python3.7/site-packages/django/urls/resolvers.py", line 602, in url_patterns
    patterns = getattr(self.urlconf_module, "urlpatterns", self.urlconf_module)
  File "/home/ramabitc/virtualenv/ramabit/3.7/lib/python3.7/site-packages/django/utils/functional.py", line 48, in __get__
    res = instance.__dict__[self.name] = self.func(instance)
  File "/home/ramabitc/virtualenv/ramabit/3.7/lib/python3.7/site-packages/django/urls/resolvers.py", line 595, in urlconf_module
    return import_module(self.urlconf_name)
  File "/opt/alt/python37/lib64/python3.7/importlib/__init__.py", line 127, in import_module
    return _bootstrap._gcd_import(name[level:], package, level)
  File "<frozen importlib._bootstrap>", line 1006, in _gcd_import
  File "<frozen importlib._bootstrap>", line 983, in _find_and_load
  File "<frozen importlib._bootstrap>", line 967, in _find_and_load_unlocked
  File "<frozen importlib._bootstrap>", line 677, in _load_unlocked
  File "<frozen importlib._bootstrap_external>", line 728, in exec_module
  File "<frozen importlib._bootstrap>", line 219, in _call_with_frames_removed
  File "/home/ramabitc/ramabit/commerce/urls.py", line 16, in <module>
    ] + static(settings.MEDIA_URL, document_root = settings.MEDIA_ROOT)+ static(settings.STATIC_URL, document_root=settings.STATIC_ROOT)
  File "/home/ramabitc/virtualenv/ramabit/3.7/lib/python3.7/site-packages/django/urls/conf.py", line 34, in include
    urlconf_module = import_module(urlconf_module)
  File "/opt/alt/python37/lib64/python3.7/importlib/__init__.py", line 127, in import_module
    return _bootstrap._gcd_import(name[level:], package, level)
  File "<frozen importlib._bootstrap>", line 1006, in _gcd_import
  File "<frozen importlib._bootstrap>", line 983, in _find_and_load
  File "<frozen importlib._bootstrap>", line 967, in _find_and_load_unlocked
  File "<frozen importlib._bootstrap>", line 677, in _load_unlocked
  File "<frozen importlib._bootstrap_external>", line 728, in exec_module
  File "<frozen importlib._bootstrap>", line 219, in _call_with_frames_removed
  File "/home/ramabitc/ramabit/admin/urls.py", line 8, in <module>
    from . import views
  File "/home/ramabitc/ramabit/admin/views.py", line 721
    if 'pic' in request.FILES:
    ^
IndentationError: unexpected indent
Internal Server Error: /api/v1/admin/miner/9
Traceback (most recent call last):
  File "/home/ramabitc/virtualenv/ramabit/3.7/lib/python3.7/site-packages/django/core/handlers/exception.py", line 47, in inner
    response = get_response(request)
  File "/home/ramabitc/virtualenv/ramabit/3.7/lib/python3.7/site-packages/django/utils/deprecation.py", line 116, in __call__
    response = self.process_request(request)
  File "/home/ramabitc/virtualenv/ramabit/3.7/lib/python3.7/site-packages/django/middleware/common.py", line 53, in process_request
    if self.should_redirect_with_slash(request):
  File "/home/ramabitc/virtualenv/ramabit/3.7/lib/python3.7/site-packages/django/middleware/common.py", line 70, in should_redirect_with_slash
    if not is_valid_path(request.path_info, urlconf):
  File "/home/ramabitc/virtualenv/ramabit/3.7/lib/python3.7/site-packages/django/urls/base.py", line 153, in is_valid_path
    return resolve(path, urlconf)
  File "/home/ramabitc/virtualenv/ramabit/3.7/lib/python3.7/site-packages/django/urls/base.py", line 24, in resolve
    return get_resolver(urlconf).resolve(path)
  File "/home/ramabitc/virtualenv/ramabit/3.7/lib/python3.7/site-packages/django/urls/resolvers.py", line 560, in resolve
    for pattern in self.url_patterns:
  File "/home/ramabitc/virtualenv/ramabit/3.7/lib/python3.7/site-packages/django/utils/functional.py", line 48, in __get__
    res = instance.__dict__[self.name] = self.func(instance)
  File "/home/ramabitc/virtualenv/ramabit/3.7/lib/python3.7/site-packages/django/urls/resolvers.py", line 602, in url_patterns
    patterns = getattr(self.urlconf_module, "urlpatterns", self.urlconf_module)
  File "/home/ramabitc/virtualenv/ramabit/3.7/lib/python3.7/site-packages/django/utils/functional.py", line 48, in __get__
    res = instance.__dict__[self.name] = self.func(instance)
  File "/home/ramabitc/virtualenv/ramabit/3.7/lib/python3.7/site-packages/django/urls/resolvers.py", line 595, in urlconf_module
    return import_module(self.urlconf_name)
  File "/opt/alt/python37/lib64/python3.7/importlib/__init__.py", line 127, in import_module
    return _bootstrap._gcd_import(name[level:], package, level)
  File "<frozen importlib._bootstrap>", line 1006, in _gcd_import
  File "<frozen importlib._bootstrap>", line 983, in _find_and_load
  File "<frozen importlib._bootstrap>", line 967, in _find_and_load_unlocked
  File "<frozen importlib._bootstrap>", line 677, in _load_unlocked
  File "<frozen importlib._bootstrap_external>", line 728, in exec_module
  File "<frozen importlib._bootstrap>", line 219, in _call_with_frames_removed
  File "/home/ramabitc/ramabit/commerce/urls.py", line 16, in <module>
    ] + static(settings.MEDIA_URL, document_root = settings.MEDIA_ROOT)+ static(settings.STATIC_URL, document_root=settings.STATIC_ROOT)
  File "/home/ramabitc/virtualenv/ramabit/3.7/lib/python3.7/site-packages/django/urls/conf.py", line 34, in include
    urlconf_module = import_module(urlconf_module)
  File "/opt/alt/python37/lib64/python3.7/importlib/__init__.py", line 127, in import_module
    return _bootstrap._gcd_import(name[level:], package, level)
  File "<frozen importlib._bootstrap>", line 1006, in _gcd_import
  File "<frozen importlib._bootstrap>", line 983, in _find_and_load
  File "<frozen importlib._bootstrap>", line 967, in _find_and_load_unlocked
  File "<frozen importlib._bootstrap>", line 677, in _load_unlocked
  File "<frozen importlib._bootstrap_external>", line 728, in exec_module
  File "<frozen importlib._bootstrap>", line 219, in _call_with_frames_removed
  File "/home/ramabitc/ramabit/admin/urls.py", line 8, in <module>
    from . import views
  File "/home/ramabitc/ramabit/admin/views.py", line 721
    if 'pic' in request.FILES:
    ^
IndentationError: unexpected indent
Internal Server Error: /api/v1/admin/miner/9
Traceback (most recent call last):
  File "/home/ramabitc/virtualenv/ramabit/3.7/lib/python3.7/site-packages/django/core/handlers/exception.py", line 47, in inner
    response = get_response(request)
  File "/home/ramabitc/virtualenv/ramabit/3.7/lib/python3.7/site-packages/django/utils/deprecation.py", line 116, in __call__
    response = self.process_request(request)
  File "/home/ramabitc/virtualenv/ramabit/3.7/lib/python3.7/site-packages/django/middleware/common.py", line 53, in process_request
    if self.should_redirect_with_slash(request):
  File "/home/ramabitc/virtualenv/ramabit/3.7/lib/python3.7/site-packages/django/middleware/common.py", line 70, in should_redirect_with_slash
    if not is_valid_path(request.path_info, urlconf):
  File "/home/ramabitc/virtualenv/ramabit/3.7/lib/python3.7/site-packages/django/urls/base.py", line 153, in is_valid_path
    return resolve(path, urlconf)
  File "/home/ramabitc/virtualenv/ramabit/3.7/lib/python3.7/site-packages/django/urls/base.py", line 24, in resolve
    return get_resolver(urlconf).resolve(path)
  File "/home/ramabitc/virtualenv/ramabit/3.7/lib/python3.7/site-packages/django/urls/resolvers.py", line 560, in resolve
    for pattern in self.url_patterns:
  File "/home/ramabitc/virtualenv/ramabit/3.7/lib/python3.7/site-packages/django/utils/functional.py", line 48, in __get__
    res = instance.__dict__[self.name] = self.func(instance)
  File "/home/ramabitc/virtualenv/ramabit/3.7/lib/python3.7/site-packages/django/urls/resolvers.py", line 602, in url_patterns
    patterns = getattr(self.urlconf_module, "urlpatterns", self.urlconf_module)
  File "/home/ramabitc/virtualenv/ramabit/3.7/lib/python3.7/site-packages/django/utils/functional.py", line 48, in __get__
    res = instance.__dict__[self.name] = self.func(instance)
  File "/home/ramabitc/virtualenv/ramabit/3.7/lib/python3.7/site-packages/django/urls/resolvers.py", line 595, in urlconf_module
    return import_module(self.urlconf_name)
  File "/opt/alt/python37/lib64/python3.7/importlib/__init__.py", line 127, in import_module
    return _bootstrap._gcd_import(name[level:], package, level)
  File "<frozen importlib._bootstrap>", line 1006, in _gcd_import
  File "<frozen importlib._bootstrap>", line 983, in _find_and_load
  File "<frozen importlib._bootstrap>", line 967, in _find_and_load_unlocked
  File "<frozen importlib._bootstrap>", line 677, in _load_unlocked
  File "<frozen importlib._bootstrap_external>", line 728, in exec_module
  File "<frozen importlib._bootstrap>", line 219, in _call_with_frames_removed
  File "/home/ramabitc/ramabit/commerce/urls.py", line 16, in <module>
    ] + static(settings.MEDIA_URL, document_root = settings.MEDIA_ROOT)+ static(settings.STATIC_URL, document_root=settings.STATIC_ROOT)
  File "/home/ramabitc/virtualenv/ramabit/3.7/lib/python3.7/site-packages/django/urls/conf.py", line 34, in include
    urlconf_module = import_module(urlconf_module)
  File "/opt/alt/python37/lib64/python3.7/importlib/__init__.py", line 127, in import_module
    return _bootstrap._gcd_import(name[level:], package, level)
  File "<frozen importlib._bootstrap>", line 1006, in _gcd_import
  File "<frozen importlib._bootstrap>", line 983, in _find_and_load
  File "<frozen importlib._bootstrap>", line 967, in _find_and_load_unlocked
  File "<frozen importlib._bootstrap>", line 677, in _load_unlocked
  File "<frozen importlib._bootstrap_external>", line 728, in exec_module
  File "<frozen importlib._bootstrap>", line 219, in _call_with_frames_removed
  File "/home/ramabitc/ramabit/admin/urls.py", line 8, in <module>
    from . import views
  File "/home/ramabitc/ramabit/admin/views.py", line 721
    if 'pic' in request.FILES:
    ^
IndentationError: unexpected indent
Internal Server Error: /api/v1/admin/miner/9
Traceback (most recent call last):
  File "/home/ramabitc/virtualenv/ramabit/3.7/lib/python3.7/site-packages/django/core/handlers/exception.py", line 47, in inner
    response = get_response(request)
  File "/home/ramabitc/virtualenv/ramabit/3.7/lib/python3.7/site-packages/django/core/handlers/base.py", line 181, in _get_response
    response = wrapped_callback(request, *callback_args, **callback_kwargs)
  File "/home/ramabitc/virtualenv/ramabit/3.7/lib/python3.7/site-packages/django/views/decorators/csrf.py", line 54, in wrapped_view
    return view_func(*args, **kwargs)
  File "/home/ramabitc/virtualenv/ramabit/3.7/lib/python3.7/site-packages/django/views/generic/base.py", line 70, in view
    return self.dispatch(request, *args, **kwargs)
  File "/home/ramabitc/virtualenv/ramabit/3.7/lib/python3.7/site-packages/rest_framework/views.py", line 509, in dispatch
    response = self.handle_exception(exc)
  File "/home/ramabitc/virtualenv/ramabit/3.7/lib/python3.7/site-packages/rest_framework/views.py", line 469, in handle_exception
    self.raise_uncaught_exception(exc)
  File "/home/ramabitc/virtualenv/ramabit/3.7/lib/python3.7/site-packages/rest_framework/views.py", line 480, in raise_uncaught_exception
    raise exc
  File "/home/ramabitc/virtualenv/ramabit/3.7/lib/python3.7/site-packages/rest_framework/views.py", line 506, in dispatch
    response = handler(request, *args, **kwargs)
  File "/home/ramabitc/ramabit/admin/views.py", line 723, in put
    auc = models.Miners(title = title , des = des , period = period , currency=models.currencies.objects.get(name = cur), price=price, rate=rate, profit=profit, pic= pic)
NameError: name 'title' is not defined
Internal Server Error: /api/v1/admin/miner/9
Traceback (most recent call last):
  File "/home/ramabitc/virtualenv/ramabit/3.7/lib/python3.7/site-packages/django/core/handlers/exception.py", line 47, in inner
    response = get_response(request)
  File "/home/ramabitc/virtualenv/ramabit/3.7/lib/python3.7/site-packages/django/core/handlers/base.py", line 181, in _get_response
    response = wrapped_callback(request, *callback_args, **callback_kwargs)
  File "/home/ramabitc/virtualenv/ramabit/3.7/lib/python3.7/site-packages/django/views/decorators/csrf.py", line 54, in wrapped_view
    return view_func(*args, **kwargs)
  File "/home/ramabitc/virtualenv/ramabit/3.7/lib/python3.7/site-packages/django/views/generic/base.py", line 70, in view
    return self.dispatch(request, *args, **kwargs)
  File "/home/ramabitc/virtualenv/ramabit/3.7/lib/python3.7/site-packages/rest_framework/views.py", line 509, in dispatch
    response = self.handle_exception(exc)
  File "/home/ramabitc/virtualenv/ramabit/3.7/lib/python3.7/site-packages/rest_framework/views.py", line 469, in handle_exception
    self.raise_uncaught_exception(exc)
  File "/home/ramabitc/virtualenv/ramabit/3.7/lib/python3.7/site-packages/rest_framework/views.py", line 480, in raise_uncaught_exception
    raise exc
  File "/home/ramabitc/virtualenv/ramabit/3.7/lib/python3.7/site-packages/rest_framework/views.py", line 506, in dispatch
    response = handler(request, *args, **kwargs)
  File "/home/ramabitc/ramabit/admin/views.py", line 723, in put
    auc.pic = pic
NameError: name 'title' is not defined
