Internal Server Error: /api/v1/inv
Traceback (most recent call last):
  File "/home/ramabitc/virtualenv/ramabit/3.7/lib/python3.7/site-packages/django/core/handlers/exception.py", line 47, in inner
    response = get_response(request)
  File "/home/ramabitc/virtualenv/ramabit/3.7/lib/python3.7/site-packages/django/core/handlers/base.py", line 181, in _get_response
    response = wrapped_callback(request, *callback_args, **callback_kwargs)
  File "/home/ramabitc/virtualenv/ramabit/3.7/lib/python3.7/site-packages/django/views/decorators/csrf.py", line 54, in wrapped_view
    return view_func(*args, **kwargs)
  File "/home/ramabitc/virtualenv/ramabit/3.7/lib/python3.7/site-packages/django/views/generic/base.py", line 70, in view
    return self.dispatch(request, *args, **kwargs)
  File "/home/ramabitc/virtualenv/ramabit/3.7/lib/python3.7/site-packages/rest_framework/views.py", line 509, in dispatch
    response = self.handle_exception(exc)
  File "/home/ramabitc/virtualenv/ramabit/3.7/lib/python3.7/site-packages/rest_framework/views.py", line 469, in handle_exception
    self.raise_uncaught_exception(exc)
  File "/home/ramabitc/virtualenv/ramabit/3.7/lib/python3.7/site-packages/rest_framework/views.py", line 480, in raise_uncaught_exception
    raise exc
  File "/home/ramabitc/virtualenv/ramabit/3.7/lib/python3.7/site-packages/rest_framework/views.py", line 506, in dispatch
    response = handler(request, *args, **kwargs)
  File "/home/ramabitc/ramabit/api/views.py", line 40, in post
    user = User.objects.get(username = request.data['username'])
KeyError: 'username'
Internal Server Error: /api/v1/inv
Traceback (most recent call last):
  File "/home/ramabitc/virtualenv/ramabit/3.7/lib/python3.7/site-packages/django/core/handlers/exception.py", line 47, in inner
    response = get_response(request)
  File "/home/ramabitc/virtualenv/ramabit/3.7/lib/python3.7/site-packages/django/core/handlers/base.py", line 181, in _get_response
    response = wrapped_callback(request, *callback_args, **callback_kwargs)
  File "/home/ramabitc/virtualenv/ramabit/3.7/lib/python3.7/site-packages/django/views/decorators/csrf.py", line 54, in wrapped_view
    return view_func(*args, **kwargs)
  File "/home/ramabitc/virtualenv/ramabit/3.7/lib/python3.7/site-packages/django/views/generic/base.py", line 70, in view
    return self.dispatch(request, *args, **kwargs)
  File "/home/ramabitc/virtualenv/ramabit/3.7/lib/python3.7/site-packages/rest_framework/views.py", line 509, in dispatch
    response = self.handle_exception(exc)
  File "/home/ramabitc/virtualenv/ramabit/3.7/lib/python3.7/site-packages/rest_framework/views.py", line 469, in handle_exception
    self.raise_uncaught_exception(exc)
  File "/home/ramabitc/virtualenv/ramabit/3.7/lib/python3.7/site-packages/rest_framework/views.py", line 480, in raise_uncaught_exception
    raise exc
  File "/home/ramabitc/virtualenv/ramabit/3.7/lib/python3.7/site-packages/rest_framework/views.py", line 506, in dispatch
    response = handler(request, *args, **kwargs)
  File "/home/ramabitc/ramabit/api/views.py", line 40, in post
    user = User.objects.get(username = request.data['username'])
KeyError: 'username'
Internal Server Error: /api/v1/inv
Traceback (most recent call last):
  File "/home/ramabitc/virtualenv/ramabit/3.7/lib/python3.7/site-packages/django/core/handlers/exception.py", line 47, in inner
    response = get_response(request)
  File "/home/ramabitc/virtualenv/ramabit/3.7/lib/python3.7/site-packages/django/core/handlers/base.py", line 181, in _get_response
    response = wrapped_callback(request, *callback_args, **callback_kwargs)
  File "/home/ramabitc/virtualenv/ramabit/3.7/lib/python3.7/site-packages/django/views/decorators/csrf.py", line 54, in wrapped_view
    return view_func(*args, **kwargs)
  File "/home/ramabitc/virtualenv/ramabit/3.7/lib/python3.7/site-packages/django/views/generic/base.py", line 70, in view
    return self.dispatch(request, *args, **kwargs)
  File "/home/ramabitc/virtualenv/ramabit/3.7/lib/python3.7/site-packages/rest_framework/views.py", line 509, in dispatch
    response = self.handle_exception(exc)
  File "/home/ramabitc/virtualenv/ramabit/3.7/lib/python3.7/site-packages/rest_framework/views.py", line 469, in handle_exception
    self.raise_uncaught_exception(exc)
  File "/home/ramabitc/virtualenv/ramabit/3.7/lib/python3.7/site-packages/rest_framework/views.py", line 480, in raise_uncaught_exception
    raise exc
  File "/home/ramabitc/virtualenv/ramabit/3.7/lib/python3.7/site-packages/rest_framework/views.py", line 506, in dispatch
    response = handler(request, *args, **kwargs)
  File "/home/ramabitc/ramabit/api/views.py", line 40, in post
    user = User.objects.get(username = request.data['username'])
KeyError: 'username'
Internal Server Error: /api/v1/inv
Traceback (most recent call last):
  File "/home/ramabitc/virtualenv/ramabit/3.7/lib/python3.7/site-packages/django/core/handlers/exception.py", line 47, in inner
    response = get_response(request)
  File "/home/ramabitc/virtualenv/ramabit/3.7/lib/python3.7/site-packages/django/core/handlers/base.py", line 181, in _get_response
    response = wrapped_callback(request, *callback_args, **callback_kwargs)
  File "/home/ramabitc/virtualenv/ramabit/3.7/lib/python3.7/site-packages/django/views/decorators/csrf.py", line 54, in wrapped_view
    return view_func(*args, **kwargs)
  File "/home/ramabitc/virtualenv/ramabit/3.7/lib/python3.7/site-packages/django/views/generic/base.py", line 70, in view
    return self.dispatch(request, *args, **kwargs)
  File "/home/ramabitc/virtualenv/ramabit/3.7/lib/python3.7/site-packages/rest_framework/views.py", line 509, in dispatch
    response = self.handle_exception(exc)
  File "/home/ramabitc/virtualenv/ramabit/3.7/lib/python3.7/site-packages/rest_framework/views.py", line 469, in handle_exception
    self.raise_uncaught_exception(exc)
  File "/home/ramabitc/virtualenv/ramabit/3.7/lib/python3.7/site-packages/rest_framework/views.py", line 480, in raise_uncaught_exception
    raise exc
  File "/home/ramabitc/virtualenv/ramabit/3.7/lib/python3.7/site-packages/rest_framework/views.py", line 506, in dispatch
    response = handler(request, *args, **kwargs)
  File "/home/ramabitc/ramabit/api/views.py", line 40, in post
    user = User.objects.get(username = request.data['username'])
KeyError: 'username'
Internal Server Error: /api/v1/inv
Traceback (most recent call last):
  File "/home/ramabitc/virtualenv/ramabit/3.7/lib/python3.7/site-packages/django/core/handlers/exception.py", line 47, in inner
    response = get_response(request)
  File "/home/ramabitc/virtualenv/ramabit/3.7/lib/python3.7/site-packages/django/core/handlers/base.py", line 181, in _get_response
    response = wrapped_callback(request, *callback_args, **callback_kwargs)
  File "/home/ramabitc/virtualenv/ramabit/3.7/lib/python3.7/site-packages/django/views/decorators/csrf.py", line 54, in wrapped_view
    return view_func(*args, **kwargs)
  File "/home/ramabitc/virtualenv/ramabit/3.7/lib/python3.7/site-packages/django/views/generic/base.py", line 70, in view
    return self.dispatch(request, *args, **kwargs)
  File "/home/ramabitc/virtualenv/ramabit/3.7/lib/python3.7/site-packages/rest_framework/views.py", line 509, in dispatch
    response = self.handle_exception(exc)
  File "/home/ramabitc/virtualenv/ramabit/3.7/lib/python3.7/site-packages/rest_framework/views.py", line 469, in handle_exception
    self.raise_uncaught_exception(exc)
  File "/home/ramabitc/virtualenv/ramabit/3.7/lib/python3.7/site-packages/rest_framework/views.py", line 480, in raise_uncaught_exception
    raise exc
  File "/home/ramabitc/virtualenv/ramabit/3.7/lib/python3.7/site-packages/rest_framework/views.py", line 506, in dispatch
    response = handler(request, *args, **kwargs)
  File "/home/ramabitc/ramabit/api/views.py", line 40, in post
    user = User.objects.get(username = request.data['username'])
KeyError: 'username'
Internal Server Error: /api/v1/inv
Traceback (most recent call last):
  File "/home/ramabitc/virtualenv/ramabit/3.7/lib/python3.7/site-packages/django/core/handlers/exception.py", line 47, in inner
    response = get_response(request)
  File "/home/ramabitc/virtualenv/ramabit/3.7/lib/python3.7/site-packages/django/core/handlers/base.py", line 181, in _get_response
    response = wrapped_callback(request, *callback_args, **callback_kwargs)
  File "/home/ramabitc/virtualenv/ramabit/3.7/lib/python3.7/site-packages/django/views/decorators/csrf.py", line 54, in wrapped_view
    return view_func(*args, **kwargs)
  File "/home/ramabitc/virtualenv/ramabit/3.7/lib/python3.7/site-packages/django/views/generic/base.py", line 70, in view
    return self.dispatch(request, *args, **kwargs)
  File "/home/ramabitc/virtualenv/ramabit/3.7/lib/python3.7/site-packages/rest_framework/views.py", line 509, in dispatch
    response = self.handle_exception(exc)
  File "/home/ramabitc/virtualenv/ramabit/3.7/lib/python3.7/site-packages/rest_framework/views.py", line 469, in handle_exception
    self.raise_uncaught_exception(exc)
  File "/home/ramabitc/virtualenv/ramabit/3.7/lib/python3.7/site-packages/rest_framework/views.py", line 480, in raise_uncaught_exception
    raise exc
  File "/home/ramabitc/virtualenv/ramabit/3.7/lib/python3.7/site-packages/rest_framework/views.py", line 506, in dispatch
    response = handler(request, *args, **kwargs)
  File "/home/ramabitc/ramabit/api/views.py", line 40, in post
    user = User.objects.get(username = request.data['username'])
KeyError: 'username'
Internal Server Error: /api/v1/inv
Traceback (most recent call last):
  File "/home/ramabitc/virtualenv/ramabit/3.7/lib/python3.7/site-packages/django/core/handlers/exception.py", line 47, in inner
    response = get_response(request)
  File "/home/ramabitc/virtualenv/ramabit/3.7/lib/python3.7/site-packages/django/core/handlers/base.py", line 181, in _get_response
    response = wrapped_callback(request, *callback_args, **callback_kwargs)
  File "/home/ramabitc/virtualenv/ramabit/3.7/lib/python3.7/site-packages/django/views/decorators/csrf.py", line 54, in wrapped_view
    return view_func(*args, **kwargs)
  File "/home/ramabitc/virtualenv/ramabit/3.7/lib/python3.7/site-packages/django/views/generic/base.py", line 70, in view
    return self.dispatch(request, *args, **kwargs)
  File "/home/ramabitc/virtualenv/ramabit/3.7/lib/python3.7/site-packages/rest_framework/views.py", line 509, in dispatch
    response = self.handle_exception(exc)
  File "/home/ramabitc/virtualenv/ramabit/3.7/lib/python3.7/site-packages/rest_framework/views.py", line 469, in handle_exception
    self.raise_uncaught_exception(exc)
  File "/home/ramabitc/virtualenv/ramabit/3.7/lib/python3.7/site-packages/rest_framework/views.py", line 480, in raise_uncaught_exception
    raise exc
  File "/home/ramabitc/virtualenv/ramabit/3.7/lib/python3.7/site-packages/rest_framework/views.py", line 506, in dispatch
    response = handler(request, *args, **kwargs)
  File "/home/ramabitc/ramabit/api/views.py", line 40, in post
    user = User.objects.get(username = request.data['username'])
KeyError: 'username'
Internal Server Error: /api/v1/inv
Traceback (most recent call last):
  File "/home/ramabitc/virtualenv/ramabit/3.7/lib/python3.7/site-packages/django/core/handlers/exception.py", line 47, in inner
    response = get_response(request)
  File "/home/ramabitc/virtualenv/ramabit/3.7/lib/python3.7/site-packages/django/core/handlers/base.py", line 181, in _get_response
    response = wrapped_callback(request, *callback_args, **callback_kwargs)
  File "/home/ramabitc/virtualenv/ramabit/3.7/lib/python3.7/site-packages/django/views/decorators/csrf.py", line 54, in wrapped_view
    return view_func(*args, **kwargs)
  File "/home/ramabitc/virtualenv/ramabit/3.7/lib/python3.7/site-packages/django/views/generic/base.py", line 70, in view
    return self.dispatch(request, *args, **kwargs)
  File "/home/ramabitc/virtualenv/ramabit/3.7/lib/python3.7/site-packages/rest_framework/views.py", line 509, in dispatch
    response = self.handle_exception(exc)
  File "/home/ramabitc/virtualenv/ramabit/3.7/lib/python3.7/site-packages/rest_framework/views.py", line 469, in handle_exception
    self.raise_uncaught_exception(exc)
  File "/home/ramabitc/virtualenv/ramabit/3.7/lib/python3.7/site-packages/rest_framework/views.py", line 480, in raise_uncaught_exception
    raise exc
  File "/home/ramabitc/virtualenv/ramabit/3.7/lib/python3.7/site-packages/rest_framework/views.py", line 506, in dispatch
    response = handler(request, *args, **kwargs)
  File "/home/ramabitc/ramabit/api/views.py", line 40, in post
    user = User.objects.get(username = request.data['username'])
KeyError: 'username'
Internal Server Error: /api/v1/inv
Traceback (most recent call last):
  File "/home/ramabitc/virtualenv/ramabit/3.7/lib/python3.7/site-packages/django/core/handlers/exception.py", line 47, in inner
    response = get_response(request)
  File "/home/ramabitc/virtualenv/ramabit/3.7/lib/python3.7/site-packages/django/core/handlers/base.py", line 181, in _get_response
    response = wrapped_callback(request, *callback_args, **callback_kwargs)
  File "/home/ramabitc/virtualenv/ramabit/3.7/lib/python3.7/site-packages/django/views/decorators/csrf.py", line 54, in wrapped_view
    return view_func(*args, **kwargs)
  File "/home/ramabitc/virtualenv/ramabit/3.7/lib/python3.7/site-packages/django/views/generic/base.py", line 70, in view
    return self.dispatch(request, *args, **kwargs)
  File "/home/ramabitc/virtualenv/ramabit/3.7/lib/python3.7/site-packages/rest_framework/views.py", line 509, in dispatch
    response = self.handle_exception(exc)
  File "/home/ramabitc/virtualenv/ramabit/3.7/lib/python3.7/site-packages/rest_framework/views.py", line 469, in handle_exception
    self.raise_uncaught_exception(exc)
  File "/home/ramabitc/virtualenv/ramabit/3.7/lib/python3.7/site-packages/rest_framework/views.py", line 480, in raise_uncaught_exception
    raise exc
  File "/home/ramabitc/virtualenv/ramabit/3.7/lib/python3.7/site-packages/rest_framework/views.py", line 506, in dispatch
    response = handler(request, *args, **kwargs)
  File "/home/ramabitc/ramabit/api/views.py", line 40, in post
    user = User.objects.get(username = request.data['username'])
KeyError: 'username'
Internal Server Error: /api/v1/inv
Traceback (most recent call last):
  File "/home/ramabitc/virtualenv/ramabit/3.7/lib/python3.7/site-packages/django/core/handlers/exception.py", line 47, in inner
    response = get_response(request)
  File "/home/ramabitc/virtualenv/ramabit/3.7/lib/python3.7/site-packages/django/core/handlers/base.py", line 181, in _get_response
    response = wrapped_callback(request, *callback_args, **callback_kwargs)
  File "/home/ramabitc/virtualenv/ramabit/3.7/lib/python3.7/site-packages/django/views/decorators/csrf.py", line 54, in wrapped_view
    return view_func(*args, **kwargs)
  File "/home/ramabitc/virtualenv/ramabit/3.7/lib/python3.7/site-packages/django/views/generic/base.py", line 70, in view
    return self.dispatch(request, *args, **kwargs)
  File "/home/ramabitc/virtualenv/ramabit/3.7/lib/python3.7/site-packages/rest_framework/views.py", line 509, in dispatch
    response = self.handle_exception(exc)
  File "/home/ramabitc/virtualenv/ramabit/3.7/lib/python3.7/site-packages/rest_framework/views.py", line 469, in handle_exception
    self.raise_uncaught_exception(exc)
  File "/home/ramabitc/virtualenv/ramabit/3.7/lib/python3.7/site-packages/rest_framework/views.py", line 480, in raise_uncaught_exception
    raise exc
  File "/home/ramabitc/virtualenv/ramabit/3.7/lib/python3.7/site-packages/rest_framework/views.py", line 506, in dispatch
    response = handler(request, *args, **kwargs)
  File "/home/ramabitc/ramabit/api/views.py", line 40, in post
    user = User.objects.get(username = request.data['username'])
KeyError: 'username'
Internal Server Error: /api/v1/inv
Traceback (most recent call last):
  File "/home/ramabitc/virtualenv/ramabit/3.7/lib/python3.7/site-packages/django/core/handlers/exception.py", line 47, in inner
    response = get_response(request)
  File "/home/ramabitc/virtualenv/ramabit/3.7/lib/python3.7/site-packages/django/core/handlers/base.py", line 181, in _get_response
    response = wrapped_callback(request, *callback_args, **callback_kwargs)
  File "/home/ramabitc/virtualenv/ramabit/3.7/lib/python3.7/site-packages/django/views/decorators/csrf.py", line 54, in wrapped_view
    return view_func(*args, **kwargs)
  File "/home/ramabitc/virtualenv/ramabit/3.7/lib/python3.7/site-packages/django/views/generic/base.py", line 70, in view
    return self.dispatch(request, *args, **kwargs)
  File "/home/ramabitc/virtualenv/ramabit/3.7/lib/python3.7/site-packages/rest_framework/views.py", line 509, in dispatch
    response = self.handle_exception(exc)
  File "/home/ramabitc/virtualenv/ramabit/3.7/lib/python3.7/site-packages/rest_framework/views.py", line 469, in handle_exception
    self.raise_uncaught_exception(exc)
  File "/home/ramabitc/virtualenv/ramabit/3.7/lib/python3.7/site-packages/rest_framework/views.py", line 480, in raise_uncaught_exception
    raise exc
  File "/home/ramabitc/virtualenv/ramabit/3.7/lib/python3.7/site-packages/rest_framework/views.py", line 506, in dispatch
    response = handler(request, *args, **kwargs)
  File "/home/ramabitc/ramabit/api/views.py", line 40, in post
    user = User.objects.get(username = request.data['username'])
KeyError: 'username'
Internal Server Error: /api/v1/inv
Traceback (most recent call last):
  File "/home/ramabitc/virtualenv/ramabit/3.7/lib/python3.7/site-packages/django/core/handlers/exception.py", line 47, in inner
    response = get_response(request)
  File "/home/ramabitc/virtualenv/ramabit/3.7/lib/python3.7/site-packages/django/core/handlers/base.py", line 181, in _get_response
    response = wrapped_callback(request, *callback_args, **callback_kwargs)
  File "/home/ramabitc/virtualenv/ramabit/3.7/lib/python3.7/site-packages/django/views/decorators/csrf.py", line 54, in wrapped_view
    return view_func(*args, **kwargs)
  File "/home/ramabitc/virtualenv/ramabit/3.7/lib/python3.7/site-packages/django/views/generic/base.py", line 70, in view
    return self.dispatch(request, *args, **kwargs)
  File "/home/ramabitc/virtualenv/ramabit/3.7/lib/python3.7/site-packages/rest_framework/views.py", line 509, in dispatch
    response = self.handle_exception(exc)
  File "/home/ramabitc/virtualenv/ramabit/3.7/lib/python3.7/site-packages/rest_framework/views.py", line 469, in handle_exception
    self.raise_uncaught_exception(exc)
  File "/home/ramabitc/virtualenv/ramabit/3.7/lib/python3.7/site-packages/rest_framework/views.py", line 480, in raise_uncaught_exception
    raise exc
  File "/home/ramabitc/virtualenv/ramabit/3.7/lib/python3.7/site-packages/rest_framework/views.py", line 506, in dispatch
    response = handler(request, *args, **kwargs)
  File "/home/ramabitc/ramabit/api/views.py", line 40, in post
    user = User.objects.get(username = request.data['username'])
KeyError: 'username'
Internal Server Error: /api/v1/inv
Traceback (most recent call last):
  File "/home/ramabitc/virtualenv/ramabit/3.7/lib/python3.7/site-packages/django/core/handlers/exception.py", line 47, in inner
    response = get_response(request)
  File "/home/ramabitc/virtualenv/ramabit/3.7/lib/python3.7/site-packages/django/core/handlers/base.py", line 181, in _get_response
    response = wrapped_callback(request, *callback_args, **callback_kwargs)
  File "/home/ramabitc/virtualenv/ramabit/3.7/lib/python3.7/site-packages/django/views/decorators/csrf.py", line 54, in wrapped_view
    return view_func(*args, **kwargs)
  File "/home/ramabitc/virtualenv/ramabit/3.7/lib/python3.7/site-packages/django/views/generic/base.py", line 70, in view
    return self.dispatch(request, *args, **kwargs)
  File "/home/ramabitc/virtualenv/ramabit/3.7/lib/python3.7/site-packages/rest_framework/views.py", line 509, in dispatch
    response = self.handle_exception(exc)
  File "/home/ramabitc/virtualenv/ramabit/3.7/lib/python3.7/site-packages/rest_framework/views.py", line 469, in handle_exception
    self.raise_uncaught_exception(exc)
  File "/home/ramabitc/virtualenv/ramabit/3.7/lib/python3.7/site-packages/rest_framework/views.py", line 480, in raise_uncaught_exception
    raise exc
  File "/home/ramabitc/virtualenv/ramabit/3.7/lib/python3.7/site-packages/rest_framework/views.py", line 506, in dispatch
    response = handler(request, *args, **kwargs)
  File "/home/ramabitc/ramabit/api/views.py", line 40, in post
    user = User.objects.get(username = request.data['username'])
KeyError: 'username'
Internal Server Error: /api/v1/inv
Traceback (most recent call last):
  File "/home/ramabitc/virtualenv/ramabit/3.7/lib/python3.7/site-packages/django/core/handlers/exception.py", line 47, in inner
    response = get_response(request)
  File "/home/ramabitc/virtualenv/ramabit/3.7/lib/python3.7/site-packages/django/core/handlers/base.py", line 181, in _get_response
    response = wrapped_callback(request, *callback_args, **callback_kwargs)
  File "/home/ramabitc/virtualenv/ramabit/3.7/lib/python3.7/site-packages/django/views/decorators/csrf.py", line 54, in wrapped_view
    return view_func(*args, **kwargs)
  File "/home/ramabitc/virtualenv/ramabit/3.7/lib/python3.7/site-packages/django/views/generic/base.py", line 70, in view
    return self.dispatch(request, *args, **kwargs)
  File "/home/ramabitc/virtualenv/ramabit/3.7/lib/python3.7/site-packages/rest_framework/views.py", line 509, in dispatch
    response = self.handle_exception(exc)
  File "/home/ramabitc/virtualenv/ramabit/3.7/lib/python3.7/site-packages/rest_framework/views.py", line 469, in handle_exception
    self.raise_uncaught_exception(exc)
  File "/home/ramabitc/virtualenv/ramabit/3.7/lib/python3.7/site-packages/rest_framework/views.py", line 480, in raise_uncaught_exception
    raise exc
  File "/home/ramabitc/virtualenv/ramabit/3.7/lib/python3.7/site-packages/rest_framework/views.py", line 506, in dispatch
    response = handler(request, *args, **kwargs)
  File "/home/ramabitc/ramabit/api/views.py", line 40, in post
    user = User.objects.get(username = request.data['username'])
KeyError: 'username'
Internal Server Error: /api/v1/inv
Traceback (most recent call last):
  File "/home/ramabitc/virtualenv/ramabit/3.7/lib/python3.7/site-packages/django/core/handlers/exception.py", line 47, in inner
    response = get_response(request)
  File "/home/ramabitc/virtualenv/ramabit/3.7/lib/python3.7/site-packages/django/core/handlers/base.py", line 181, in _get_response
    response = wrapped_callback(request, *callback_args, **callback_kwargs)
  File "/home/ramabitc/virtualenv/ramabit/3.7/lib/python3.7/site-packages/django/views/decorators/csrf.py", line 54, in wrapped_view
    return view_func(*args, **kwargs)
  File "/home/ramabitc/virtualenv/ramabit/3.7/lib/python3.7/site-packages/django/views/generic/base.py", line 70, in view
    return self.dispatch(request, *args, **kwargs)
  File "/home/ramabitc/virtualenv/ramabit/3.7/lib/python3.7/site-packages/rest_framework/views.py", line 509, in dispatch
    response = self.handle_exception(exc)
  File "/home/ramabitc/virtualenv/ramabit/3.7/lib/python3.7/site-packages/rest_framework/views.py", line 469, in handle_exception
    self.raise_uncaught_exception(exc)
  File "/home/ramabitc/virtualenv/ramabit/3.7/lib/python3.7/site-packages/rest_framework/views.py", line 480, in raise_uncaught_exception
    raise exc
  File "/home/ramabitc/virtualenv/ramabit/3.7/lib/python3.7/site-packages/rest_framework/views.py", line 506, in dispatch
    response = handler(request, *args, **kwargs)
  File "/home/ramabitc/ramabit/api/views.py", line 40, in post
    user = User.objects.get(username = request.data['username'])
KeyError: 'username'
Internal Server Error: /api/v1/inv
Traceback (most recent call last):
  File "/home/ramabitc/virtualenv/ramabit/3.7/lib/python3.7/site-packages/django/core/handlers/exception.py", line 47, in inner
    response = get_response(request)
  File "/home/ramabitc/virtualenv/ramabit/3.7/lib/python3.7/site-packages/django/core/handlers/base.py", line 181, in _get_response
    response = wrapped_callback(request, *callback_args, **callback_kwargs)
  File "/home/ramabitc/virtualenv/ramabit/3.7/lib/python3.7/site-packages/django/views/decorators/csrf.py", line 54, in wrapped_view
    return view_func(*args, **kwargs)
  File "/home/ramabitc/virtualenv/ramabit/3.7/lib/python3.7/site-packages/django/views/generic/base.py", line 70, in view
    return self.dispatch(request, *args, **kwargs)
  File "/home/ramabitc/virtualenv/ramabit/3.7/lib/python3.7/site-packages/rest_framework/views.py", line 509, in dispatch
    response = self.handle_exception(exc)
  File "/home/ramabitc/virtualenv/ramabit/3.7/lib/python3.7/site-packages/rest_framework/views.py", line 469, in handle_exception
    self.raise_uncaught_exception(exc)
  File "/home/ramabitc/virtualenv/ramabit/3.7/lib/python3.7/site-packages/rest_framework/views.py", line 480, in raise_uncaught_exception
    raise exc
  File "/home/ramabitc/virtualenv/ramabit/3.7/lib/python3.7/site-packages/rest_framework/views.py", line 506, in dispatch
    response = handler(request, *args, **kwargs)
  File "/home/ramabitc/ramabit/api/views.py", line 40, in post
    user = User.objects.get(username = request.data['username'])
KeyError: 'username'
Internal Server Error: /api/v1/inv
Traceback (most recent call last):
  File "/home/ramabitc/virtualenv/ramabit/3.7/lib/python3.7/site-packages/django/core/handlers/exception.py", line 47, in inner
    response = get_response(request)
  File "/home/ramabitc/virtualenv/ramabit/3.7/lib/python3.7/site-packages/django/core/handlers/base.py", line 181, in _get_response
    response = wrapped_callback(request, *callback_args, **callback_kwargs)
  File "/home/ramabitc/virtualenv/ramabit/3.7/lib/python3.7/site-packages/django/views/decorators/csrf.py", line 54, in wrapped_view
    return view_func(*args, **kwargs)
  File "/home/ramabitc/virtualenv/ramabit/3.7/lib/python3.7/site-packages/django/views/generic/base.py", line 70, in view
    return self.dispatch(request, *args, **kwargs)
  File "/home/ramabitc/virtualenv/ramabit/3.7/lib/python3.7/site-packages/rest_framework/views.py", line 509, in dispatch
    response = self.handle_exception(exc)
  File "/home/ramabitc/virtualenv/ramabit/3.7/lib/python3.7/site-packages/rest_framework/views.py", line 469, in handle_exception
    self.raise_uncaught_exception(exc)
  File "/home/ramabitc/virtualenv/ramabit/3.7/lib/python3.7/site-packages/rest_framework/views.py", line 480, in raise_uncaught_exception
    raise exc
  File "/home/ramabitc/virtualenv/ramabit/3.7/lib/python3.7/site-packages/rest_framework/views.py", line 506, in dispatch
    response = handler(request, *args, **kwargs)
  File "/home/ramabitc/ramabit/api/views.py", line 40, in post
    user = User.objects.get(username = request.data['username'])
KeyError: 'username'
Internal Server Error: /api/v1/inv
Traceback (most recent call last):
  File "/home/ramabitc/virtualenv/ramabit/3.7/lib/python3.7/site-packages/django/core/handlers/exception.py", line 47, in inner
    response = get_response(request)
  File "/home/ramabitc/virtualenv/ramabit/3.7/lib/python3.7/site-packages/django/core/handlers/base.py", line 181, in _get_response
    response = wrapped_callback(request, *callback_args, **callback_kwargs)
  File "/home/ramabitc/virtualenv/ramabit/3.7/lib/python3.7/site-packages/django/views/decorators/csrf.py", line 54, in wrapped_view
    return view_func(*args, **kwargs)
  File "/home/ramabitc/virtualenv/ramabit/3.7/lib/python3.7/site-packages/django/views/generic/base.py", line 70, in view
    return self.dispatch(request, *args, **kwargs)
  File "/home/ramabitc/virtualenv/ramabit/3.7/lib/python3.7/site-packages/rest_framework/views.py", line 509, in dispatch
    response = self.handle_exception(exc)
  File "/home/ramabitc/virtualenv/ramabit/3.7/lib/python3.7/site-packages/rest_framework/views.py", line 469, in handle_exception
    self.raise_uncaught_exception(exc)
  File "/home/ramabitc/virtualenv/ramabit/3.7/lib/python3.7/site-packages/rest_framework/views.py", line 480, in raise_uncaught_exception
    raise exc
  File "/home/ramabitc/virtualenv/ramabit/3.7/lib/python3.7/site-packages/rest_framework/views.py", line 506, in dispatch
    response = handler(request, *args, **kwargs)
  File "/home/ramabitc/ramabit/api/views.py", line 40, in post
    user = User.objects.get(username = request.data['username'])
KeyError: 'username'
Internal Server Error: /api/v1/inv
Traceback (most recent call last):
  File "/home/ramabitc/virtualenv/ramabit/3.7/lib/python3.7/site-packages/django/core/handlers/exception.py", line 47, in inner
    response = get_response(request)
  File "/home/ramabitc/virtualenv/ramabit/3.7/lib/python3.7/site-packages/django/core/handlers/base.py", line 181, in _get_response
    response = wrapped_callback(request, *callback_args, **callback_kwargs)
  File "/home/ramabitc/virtualenv/ramabit/3.7/lib/python3.7/site-packages/django/views/decorators/csrf.py", line 54, in wrapped_view
    return view_func(*args, **kwargs)
  File "/home/ramabitc/virtualenv/ramabit/3.7/lib/python3.7/site-packages/django/views/generic/base.py", line 70, in view
    return self.dispatch(request, *args, **kwargs)
  File "/home/ramabitc/virtualenv/ramabit/3.7/lib/python3.7/site-packages/rest_framework/views.py", line 509, in dispatch
    response = self.handle_exception(exc)
  File "/home/ramabitc/virtualenv/ramabit/3.7/lib/python3.7/site-packages/rest_framework/views.py", line 469, in handle_exception
    self.raise_uncaught_exception(exc)
  File "/home/ramabitc/virtualenv/ramabit/3.7/lib/python3.7/site-packages/rest_framework/views.py", line 480, in raise_uncaught_exception
    raise exc
  File "/home/ramabitc/virtualenv/ramabit/3.7/lib/python3.7/site-packages/rest_framework/views.py", line 506, in dispatch
    response = handler(request, *args, **kwargs)
  File "/home/ramabitc/ramabit/api/views.py", line 40, in post
    user = User.objects.get(username = request.data['username'])
KeyError: 'username'
Internal Server Error: /api/v1/inv
Traceback (most recent call last):
  File "/home/ramabitc/virtualenv/ramabit/3.7/lib/python3.7/site-packages/django/core/handlers/exception.py", line 47, in inner
    response = get_response(request)
  File "/home/ramabitc/virtualenv/ramabit/3.7/lib/python3.7/site-packages/django/core/handlers/base.py", line 181, in _get_response
    response = wrapped_callback(request, *callback_args, **callback_kwargs)
  File "/home/ramabitc/virtualenv/ramabit/3.7/lib/python3.7/site-packages/django/views/decorators/csrf.py", line 54, in wrapped_view
    return view_func(*args, **kwargs)
  File "/home/ramabitc/virtualenv/ramabit/3.7/lib/python3.7/site-packages/django/views/generic/base.py", line 70, in view
    return self.dispatch(request, *args, **kwargs)
  File "/home/ramabitc/virtualenv/ramabit/3.7/lib/python3.7/site-packages/rest_framework/views.py", line 509, in dispatch
    response = self.handle_exception(exc)
  File "/home/ramabitc/virtualenv/ramabit/3.7/lib/python3.7/site-packages/rest_framework/views.py", line 469, in handle_exception
    self.raise_uncaught_exception(exc)
  File "/home/ramabitc/virtualenv/ramabit/3.7/lib/python3.7/site-packages/rest_framework/views.py", line 480, in raise_uncaught_exception
    raise exc
  File "/home/ramabitc/virtualenv/ramabit/3.7/lib/python3.7/site-packages/rest_framework/views.py", line 506, in dispatch
    response = handler(request, *args, **kwargs)
  File "/home/ramabitc/ramabit/api/views.py", line 40, in post
    user = User.objects.get(username = request.data['username'])
KeyError: 'username'
Internal Server Error: /api/v1/inv
Traceback (most recent call last):
  File "/home/ramabitc/virtualenv/ramabit/3.7/lib/python3.7/site-packages/django/core/handlers/exception.py", line 47, in inner
    response = get_response(request)
  File "/home/ramabitc/virtualenv/ramabit/3.7/lib/python3.7/site-packages/django/core/handlers/base.py", line 181, in _get_response
    response = wrapped_callback(request, *callback_args, **callback_kwargs)
  File "/home/ramabitc/virtualenv/ramabit/3.7/lib/python3.7/site-packages/django/views/decorators/csrf.py", line 54, in wrapped_view
    return view_func(*args, **kwargs)
  File "/home/ramabitc/virtualenv/ramabit/3.7/lib/python3.7/site-packages/django/views/generic/base.py", line 70, in view
    return self.dispatch(request, *args, **kwargs)
  File "/home/ramabitc/virtualenv/ramabit/3.7/lib/python3.7/site-packages/rest_framework/views.py", line 509, in dispatch
    response = self.handle_exception(exc)
  File "/home/ramabitc/virtualenv/ramabit/3.7/lib/python3.7/site-packages/rest_framework/views.py", line 469, in handle_exception
    self.raise_uncaught_exception(exc)
  File "/home/ramabitc/virtualenv/ramabit/3.7/lib/python3.7/site-packages/rest_framework/views.py", line 480, in raise_uncaught_exception
    raise exc
  File "/home/ramabitc/virtualenv/ramabit/3.7/lib/python3.7/site-packages/rest_framework/views.py", line 506, in dispatch
    response = handler(request, *args, **kwargs)
  File "/home/ramabitc/ramabit/api/views.py", line 40, in post
    user = User.objects.get(username = request.data['username'])
KeyError: 'username'
Internal Server Error: /api/v1/inv
Traceback (most recent call last):
  File "/home/ramabitc/virtualenv/ramabit/3.7/lib/python3.7/site-packages/django/core/handlers/exception.py", line 47, in inner
    response = get_response(request)
  File "/home/ramabitc/virtualenv/ramabit/3.7/lib/python3.7/site-packages/django/core/handlers/base.py", line 181, in _get_response
    response = wrapped_callback(request, *callback_args, **callback_kwargs)
  File "/home/ramabitc/virtualenv/ramabit/3.7/lib/python3.7/site-packages/django/views/decorators/csrf.py", line 54, in wrapped_view
    return view_func(*args, **kwargs)
  File "/home/ramabitc/virtualenv/ramabit/3.7/lib/python3.7/site-packages/django/views/generic/base.py", line 70, in view
    return self.dispatch(request, *args, **kwargs)
  File "/home/ramabitc/virtualenv/ramabit/3.7/lib/python3.7/site-packages/rest_framework/views.py", line 509, in dispatch
    response = self.handle_exception(exc)
  File "/home/ramabitc/virtualenv/ramabit/3.7/lib/python3.7/site-packages/rest_framework/views.py", line 469, in handle_exception
    self.raise_uncaught_exception(exc)
  File "/home/ramabitc/virtualenv/ramabit/3.7/lib/python3.7/site-packages/rest_framework/views.py", line 480, in raise_uncaught_exception
    raise exc
  File "/home/ramabitc/virtualenv/ramabit/3.7/lib/python3.7/site-packages/rest_framework/views.py", line 506, in dispatch
    response = handler(request, *args, **kwargs)
  File "/home/ramabitc/ramabit/api/views.py", line 40, in post
    user = User.objects.get(username = request.data['username'])
KeyError: 'username'
Internal Server Error: /api/v1/inv
Traceback (most recent call last):
  File "/home/ramabitc/virtualenv/ramabit/3.7/lib/python3.7/site-packages/django/core/handlers/exception.py", line 47, in inner
    response = get_response(request)
  File "/home/ramabitc/virtualenv/ramabit/3.7/lib/python3.7/site-packages/django/core/handlers/base.py", line 181, in _get_response
    response = wrapped_callback(request, *callback_args, **callback_kwargs)
  File "/home/ramabitc/virtualenv/ramabit/3.7/lib/python3.7/site-packages/django/views/decorators/csrf.py", line 54, in wrapped_view
    return view_func(*args, **kwargs)
  File "/home/ramabitc/virtualenv/ramabit/3.7/lib/python3.7/site-packages/django/views/generic/base.py", line 70, in view
    return self.dispatch(request, *args, **kwargs)
  File "/home/ramabitc/virtualenv/ramabit/3.7/lib/python3.7/site-packages/rest_framework/views.py", line 509, in dispatch
    response = self.handle_exception(exc)
  File "/home/ramabitc/virtualenv/ramabit/3.7/lib/python3.7/site-packages/rest_framework/views.py", line 469, in handle_exception
    self.raise_uncaught_exception(exc)
  File "/home/ramabitc/virtualenv/ramabit/3.7/lib/python3.7/site-packages/rest_framework/views.py", line 480, in raise_uncaught_exception
    raise exc
  File "/home/ramabitc/virtualenv/ramabit/3.7/lib/python3.7/site-packages/rest_framework/views.py", line 506, in dispatch
    response = handler(request, *args, **kwargs)
  File "/home/ramabitc/ramabit/api/views.py", line 40, in post
    user = User.objects.get(username = request.data['username'])
KeyError: 'username'
Internal Server Error: /api/v1/inv
Traceback (most recent call last):
  File "/home/ramabitc/virtualenv/ramabit/3.7/lib/python3.7/site-packages/django/core/handlers/exception.py", line 47, in inner
    response = get_response(request)
  File "/home/ramabitc/virtualenv/ramabit/3.7/lib/python3.7/site-packages/django/core/handlers/base.py", line 181, in _get_response
    response = wrapped_callback(request, *callback_args, **callback_kwargs)
  File "/home/ramabitc/virtualenv/ramabit/3.7/lib/python3.7/site-packages/django/views/decorators/csrf.py", line 54, in wrapped_view
    return view_func(*args, **kwargs)
  File "/home/ramabitc/virtualenv/ramabit/3.7/lib/python3.7/site-packages/django/views/generic/base.py", line 70, in view
    return self.dispatch(request, *args, **kwargs)
  File "/home/ramabitc/virtualenv/ramabit/3.7/lib/python3.7/site-packages/rest_framework/views.py", line 509, in dispatch
    response = self.handle_exception(exc)
  File "/home/ramabitc/virtualenv/ramabit/3.7/lib/python3.7/site-packages/rest_framework/views.py", line 469, in handle_exception
    self.raise_uncaught_exception(exc)
  File "/home/ramabitc/virtualenv/ramabit/3.7/lib/python3.7/site-packages/rest_framework/views.py", line 480, in raise_uncaught_exception
    raise exc
  File "/home/ramabitc/virtualenv/ramabit/3.7/lib/python3.7/site-packages/rest_framework/views.py", line 506, in dispatch
    response = handler(request, *args, **kwargs)
  File "/home/ramabitc/ramabit/api/views.py", line 40, in post
    user = User.objects.get(username = request.data['username'])
KeyError: 'username'
Internal Server Error: /api/v1/inv
Traceback (most recent call last):
  File "/home/ramabitc/virtualenv/ramabit/3.7/lib/python3.7/site-packages/django/core/handlers/exception.py", line 47, in inner
    response = get_response(request)
  File "/home/ramabitc/virtualenv/ramabit/3.7/lib/python3.7/site-packages/django/core/handlers/base.py", line 181, in _get_response
    response = wrapped_callback(request, *callback_args, **callback_kwargs)
  File "/home/ramabitc/virtualenv/ramabit/3.7/lib/python3.7/site-packages/django/views/decorators/csrf.py", line 54, in wrapped_view
    return view_func(*args, **kwargs)
  File "/home/ramabitc/virtualenv/ramabit/3.7/lib/python3.7/site-packages/django/views/generic/base.py", line 70, in view
    return self.dispatch(request, *args, **kwargs)
  File "/home/ramabitc/virtualenv/ramabit/3.7/lib/python3.7/site-packages/rest_framework/views.py", line 509, in dispatch
    response = self.handle_exception(exc)
  File "/home/ramabitc/virtualenv/ramabit/3.7/lib/python3.7/site-packages/rest_framework/views.py", line 469, in handle_exception
    self.raise_uncaught_exception(exc)
  File "/home/ramabitc/virtualenv/ramabit/3.7/lib/python3.7/site-packages/rest_framework/views.py", line 480, in raise_uncaught_exception
    raise exc
  File "/home/ramabitc/virtualenv/ramabit/3.7/lib/python3.7/site-packages/rest_framework/views.py", line 506, in dispatch
    response = handler(request, *args, **kwargs)
  File "/home/ramabitc/ramabit/api/views.py", line 40, in post
    user = User.objects.get(username = request.data['username'])
KeyError: 'username'
Internal Server Error: /api/v1/inv
Traceback (most recent call last):
  File "/home/ramabitc/virtualenv/ramabit/3.7/lib/python3.7/site-packages/django/core/handlers/exception.py", line 47, in inner
    response = get_response(request)
  File "/home/ramabitc/virtualenv/ramabit/3.7/lib/python3.7/site-packages/django/core/handlers/base.py", line 181, in _get_response
    response = wrapped_callback(request, *callback_args, **callback_kwargs)
  File "/home/ramabitc/virtualenv/ramabit/3.7/lib/python3.7/site-packages/django/views/decorators/csrf.py", line 54, in wrapped_view
    return view_func(*args, **kwargs)
  File "/home/ramabitc/virtualenv/ramabit/3.7/lib/python3.7/site-packages/django/views/generic/base.py", line 70, in view
    return self.dispatch(request, *args, **kwargs)
  File "/home/ramabitc/virtualenv/ramabit/3.7/lib/python3.7/site-packages/rest_framework/views.py", line 509, in dispatch
    response = self.handle_exception(exc)
  File "/home/ramabitc/virtualenv/ramabit/3.7/lib/python3.7/site-packages/rest_framework/views.py", line 469, in handle_exception
    self.raise_uncaught_exception(exc)
  File "/home/ramabitc/virtualenv/ramabit/3.7/lib/python3.7/site-packages/rest_framework/views.py", line 480, in raise_uncaught_exception
    raise exc
  File "/home/ramabitc/virtualenv/ramabit/3.7/lib/python3.7/site-packages/rest_framework/views.py", line 506, in dispatch
    response = handler(request, *args, **kwargs)
  File "/home/ramabitc/ramabit/api/views.py", line 40, in post
    user = User.objects.get(username = request.data['username'])
KeyError: 'username'
Internal Server Error: /api/v1/inv
Traceback (most recent call last):
  File "/home/ramabitc/virtualenv/ramabit/3.7/lib/python3.7/site-packages/django/core/handlers/exception.py", line 47, in inner
    response = get_response(request)
  File "/home/ramabitc/virtualenv/ramabit/3.7/lib/python3.7/site-packages/django/core/handlers/base.py", line 181, in _get_response
    response = wrapped_callback(request, *callback_args, **callback_kwargs)
  File "/home/ramabitc/virtualenv/ramabit/3.7/lib/python3.7/site-packages/django/views/decorators/csrf.py", line 54, in wrapped_view
    return view_func(*args, **kwargs)
  File "/home/ramabitc/virtualenv/ramabit/3.7/lib/python3.7/site-packages/django/views/generic/base.py", line 70, in view
    return self.dispatch(request, *args, **kwargs)
  File "/home/ramabitc/virtualenv/ramabit/3.7/lib/python3.7/site-packages/rest_framework/views.py", line 509, in dispatch
    response = self.handle_exception(exc)
  File "/home/ramabitc/virtualenv/ramabit/3.7/lib/python3.7/site-packages/rest_framework/views.py", line 469, in handle_exception
    self.raise_uncaught_exception(exc)
  File "/home/ramabitc/virtualenv/ramabit/3.7/lib/python3.7/site-packages/rest_framework/views.py", line 480, in raise_uncaught_exception
    raise exc
  File "/home/ramabitc/virtualenv/ramabit/3.7/lib/python3.7/site-packages/rest_framework/views.py", line 506, in dispatch
    response = handler(request, *args, **kwargs)
  File "/home/ramabitc/ramabit/api/views.py", line 40, in post
    user = User.objects.get(username = request.data['username'])
KeyError: 'username'
Internal Server Error: /api/v1/inv
Traceback (most recent call last):
  File "/home/ramabitc/virtualenv/ramabit/3.7/lib/python3.7/site-packages/django/core/handlers/exception.py", line 47, in inner
    response = get_response(request)
  File "/home/ramabitc/virtualenv/ramabit/3.7/lib/python3.7/site-packages/django/core/handlers/base.py", line 181, in _get_response
    response = wrapped_callback(request, *callback_args, **callback_kwargs)
  File "/home/ramabitc/virtualenv/ramabit/3.7/lib/python3.7/site-packages/django/views/decorators/csrf.py", line 54, in wrapped_view
    return view_func(*args, **kwargs)
  File "/home/ramabitc/virtualenv/ramabit/3.7/lib/python3.7/site-packages/django/views/generic/base.py", line 70, in view
    return self.dispatch(request, *args, **kwargs)
  File "/home/ramabitc/virtualenv/ramabit/3.7/lib/python3.7/site-packages/rest_framework/views.py", line 509, in dispatch
    response = self.handle_exception(exc)
  File "/home/ramabitc/virtualenv/ramabit/3.7/lib/python3.7/site-packages/rest_framework/views.py", line 469, in handle_exception
    self.raise_uncaught_exception(exc)
  File "/home/ramabitc/virtualenv/ramabit/3.7/lib/python3.7/site-packages/rest_framework/views.py", line 480, in raise_uncaught_exception
    raise exc
  File "/home/ramabitc/virtualenv/ramabit/3.7/lib/python3.7/site-packages/rest_framework/views.py", line 506, in dispatch
    response = handler(request, *args, **kwargs)
  File "/home/ramabitc/ramabit/api/views.py", line 40, in post
    user = User.objects.get(username = request.data['username'])
KeyError: 'username'
Internal Server Error: /api/v1/inv
Traceback (most recent call last):
  File "/home/ramabitc/virtualenv/ramabit/3.7/lib/python3.7/site-packages/django/core/handlers/exception.py", line 47, in inner
    response = get_response(request)
  File "/home/ramabitc/virtualenv/ramabit/3.7/lib/python3.7/site-packages/django/core/handlers/base.py", line 181, in _get_response
    response = wrapped_callback(request, *callback_args, **callback_kwargs)
  File "/home/ramabitc/virtualenv/ramabit/3.7/lib/python3.7/site-packages/django/views/decorators/csrf.py", line 54, in wrapped_view
    return view_func(*args, **kwargs)
  File "/home/ramabitc/virtualenv/ramabit/3.7/lib/python3.7/site-packages/django/views/generic/base.py", line 70, in view
    return self.dispatch(request, *args, **kwargs)
  File "/home/ramabitc/virtualenv/ramabit/3.7/lib/python3.7/site-packages/rest_framework/views.py", line 509, in dispatch
    response = self.handle_exception(exc)
  File "/home/ramabitc/virtualenv/ramabit/3.7/lib/python3.7/site-packages/rest_framework/views.py", line 469, in handle_exception
    self.raise_uncaught_exception(exc)
  File "/home/ramabitc/virtualenv/ramabit/3.7/lib/python3.7/site-packages/rest_framework/views.py", line 480, in raise_uncaught_exception
    raise exc
  File "/home/ramabitc/virtualenv/ramabit/3.7/lib/python3.7/site-packages/rest_framework/views.py", line 506, in dispatch
    response = handler(request, *args, **kwargs)
  File "/home/ramabitc/ramabit/api/views.py", line 40, in post
    user = User.objects.get(username = request.data['username'])
KeyError: 'username'
Internal Server Error: /api/v1/inv
Traceback (most recent call last):
  File "/home/ramabitc/virtualenv/ramabit/3.7/lib/python3.7/site-packages/django/core/handlers/exception.py", line 47, in inner
    response = get_response(request)
  File "/home/ramabitc/virtualenv/ramabit/3.7/lib/python3.7/site-packages/django/core/handlers/base.py", line 181, in _get_response
    response = wrapped_callback(request, *callback_args, **callback_kwargs)
  File "/home/ramabitc/virtualenv/ramabit/3.7/lib/python3.7/site-packages/django/views/decorators/csrf.py", line 54, in wrapped_view
    return view_func(*args, **kwargs)
  File "/home/ramabitc/virtualenv/ramabit/3.7/lib/python3.7/site-packages/django/views/generic/base.py", line 70, in view
    return self.dispatch(request, *args, **kwargs)
  File "/home/ramabitc/virtualenv/ramabit/3.7/lib/python3.7/site-packages/rest_framework/views.py", line 509, in dispatch
    response = self.handle_exception(exc)
  File "/home/ramabitc/virtualenv/ramabit/3.7/lib/python3.7/site-packages/rest_framework/views.py", line 469, in handle_exception
    self.raise_uncaught_exception(exc)
  File "/home/ramabitc/virtualenv/ramabit/3.7/lib/python3.7/site-packages/rest_framework/views.py", line 480, in raise_uncaught_exception
    raise exc
  File "/home/ramabitc/virtualenv/ramabit/3.7/lib/python3.7/site-packages/rest_framework/views.py", line 506, in dispatch
    response = handler(request, *args, **kwargs)
  File "/home/ramabitc/ramabit/api/views.py", line 40, in post
    user = User.objects.get(username = request.data['username'])
KeyError: 'username'
Internal Server Error: /api/v1/inv
Traceback (most recent call last):
  File "/home/ramabitc/virtualenv/ramabit/3.7/lib/python3.7/site-packages/django/core/handlers/exception.py", line 47, in inner
    response = get_response(request)
  File "/home/ramabitc/virtualenv/ramabit/3.7/lib/python3.7/site-packages/django/core/handlers/base.py", line 181, in _get_response
    response = wrapped_callback(request, *callback_args, **callback_kwargs)
  File "/home/ramabitc/virtualenv/ramabit/3.7/lib/python3.7/site-packages/django/views/decorators/csrf.py", line 54, in wrapped_view
    return view_func(*args, **kwargs)
  File "/home/ramabitc/virtualenv/ramabit/3.7/lib/python3.7/site-packages/django/views/generic/base.py", line 70, in view
    return self.dispatch(request, *args, **kwargs)
  File "/home/ramabitc/virtualenv/ramabit/3.7/lib/python3.7/site-packages/rest_framework/views.py", line 509, in dispatch
    response = self.handle_exception(exc)
  File "/home/ramabitc/virtualenv/ramabit/3.7/lib/python3.7/site-packages/rest_framework/views.py", line 469, in handle_exception
    self.raise_uncaught_exception(exc)
  File "/home/ramabitc/virtualenv/ramabit/3.7/lib/python3.7/site-packages/rest_framework/views.py", line 480, in raise_uncaught_exception
    raise exc
  File "/home/ramabitc/virtualenv/ramabit/3.7/lib/python3.7/site-packages/rest_framework/views.py", line 506, in dispatch
    response = handler(request, *args, **kwargs)
  File "/home/ramabitc/ramabit/api/views.py", line 40, in post
    user = User.objects.get(username = request.data['username'])
KeyError: 'username'
Internal Server Error: /api/v1/inv
Traceback (most recent call last):
  File "/home/ramabitc/virtualenv/ramabit/3.7/lib/python3.7/site-packages/django/core/handlers/exception.py", line 47, in inner
    response = get_response(request)
  File "/home/ramabitc/virtualenv/ramabit/3.7/lib/python3.7/site-packages/django/core/handlers/base.py", line 181, in _get_response
    response = wrapped_callback(request, *callback_args, **callback_kwargs)
  File "/home/ramabitc/virtualenv/ramabit/3.7/lib/python3.7/site-packages/django/views/decorators/csrf.py", line 54, in wrapped_view
    return view_func(*args, **kwargs)
  File "/home/ramabitc/virtualenv/ramabit/3.7/lib/python3.7/site-packages/django/views/generic/base.py", line 70, in view
    return self.dispatch(request, *args, **kwargs)
  File "/home/ramabitc/virtualenv/ramabit/3.7/lib/python3.7/site-packages/rest_framework/views.py", line 509, in dispatch
    response = self.handle_exception(exc)
  File "/home/ramabitc/virtualenv/ramabit/3.7/lib/python3.7/site-packages/rest_framework/views.py", line 469, in handle_exception
    self.raise_uncaught_exception(exc)
  File "/home/ramabitc/virtualenv/ramabit/3.7/lib/python3.7/site-packages/rest_framework/views.py", line 480, in raise_uncaught_exception
    raise exc
  File "/home/ramabitc/virtualenv/ramabit/3.7/lib/python3.7/site-packages/rest_framework/views.py", line 506, in dispatch
    response = handler(request, *args, **kwargs)
  File "/home/ramabitc/ramabit/api/views.py", line 40, in post
    user = User.objects.get(username = request.data['username'])
KeyError: 'username'
Internal Server Error: /api/v1/inv
Traceback (most recent call last):
  File "/home/ramabitc/virtualenv/ramabit/3.7/lib/python3.7/site-packages/django/core/handlers/exception.py", line 47, in inner
    response = get_response(request)
  File "/home/ramabitc/virtualenv/ramabit/3.7/lib/python3.7/site-packages/django/core/handlers/base.py", line 181, in _get_response
    response = wrapped_callback(request, *callback_args, **callback_kwargs)
  File "/home/ramabitc/virtualenv/ramabit/3.7/lib/python3.7/site-packages/django/views/decorators/csrf.py", line 54, in wrapped_view
    return view_func(*args, **kwargs)
  File "/home/ramabitc/virtualenv/ramabit/3.7/lib/python3.7/site-packages/django/views/generic/base.py", line 70, in view
    return self.dispatch(request, *args, **kwargs)
  File "/home/ramabitc/virtualenv/ramabit/3.7/lib/python3.7/site-packages/rest_framework/views.py", line 509, in dispatch
    response = self.handle_exception(exc)
  File "/home/ramabitc/virtualenv/ramabit/3.7/lib/python3.7/site-packages/rest_framework/views.py", line 469, in handle_exception
    self.raise_uncaught_exception(exc)
  File "/home/ramabitc/virtualenv/ramabit/3.7/lib/python3.7/site-packages/rest_framework/views.py", line 480, in raise_uncaught_exception
    raise exc
  File "/home/ramabitc/virtualenv/ramabit/3.7/lib/python3.7/site-packages/rest_framework/views.py", line 506, in dispatch
    response = handler(request, *args, **kwargs)
  File "/home/ramabitc/ramabit/api/views.py", line 40, in post
    user = User.objects.get(username = request.data['username'])
KeyError: 'username'
Internal Server Error: /api/v1/inv
Traceback (most recent call last):
  File "/home/ramabitc/virtualenv/ramabit/3.7/lib/python3.7/site-packages/django/core/handlers/exception.py", line 47, in inner
    response = get_response(request)
  File "/home/ramabitc/virtualenv/ramabit/3.7/lib/python3.7/site-packages/django/core/handlers/base.py", line 181, in _get_response
    response = wrapped_callback(request, *callback_args, **callback_kwargs)
  File "/home/ramabitc/virtualenv/ramabit/3.7/lib/python3.7/site-packages/django/views/decorators/csrf.py", line 54, in wrapped_view
    return view_func(*args, **kwargs)
  File "/home/ramabitc/virtualenv/ramabit/3.7/lib/python3.7/site-packages/django/views/generic/base.py", line 70, in view
    return self.dispatch(request, *args, **kwargs)
  File "/home/ramabitc/virtualenv/ramabit/3.7/lib/python3.7/site-packages/rest_framework/views.py", line 509, in dispatch
    response = self.handle_exception(exc)
  File "/home/ramabitc/virtualenv/ramabit/3.7/lib/python3.7/site-packages/rest_framework/views.py", line 469, in handle_exception
    self.raise_uncaught_exception(exc)
  File "/home/ramabitc/virtualenv/ramabit/3.7/lib/python3.7/site-packages/rest_framework/views.py", line 480, in raise_uncaught_exception
    raise exc
  File "/home/ramabitc/virtualenv/ramabit/3.7/lib/python3.7/site-packages/rest_framework/views.py", line 506, in dispatch
    response = handler(request, *args, **kwargs)
  File "/home/ramabitc/ramabit/api/views.py", line 40, in post
    user = User.objects.get(username = request.data['username'])
KeyError: 'username'
Internal Server Error: /api/v1/inv
Traceback (most recent call last):
  File "/home/ramabitc/virtualenv/ramabit/3.7/lib/python3.7/site-packages/django/core/handlers/exception.py", line 47, in inner
    response = get_response(request)
  File "/home/ramabitc/virtualenv/ramabit/3.7/lib/python3.7/site-packages/django/core/handlers/base.py", line 181, in _get_response
    response = wrapped_callback(request, *callback_args, **callback_kwargs)
  File "/home/ramabitc/virtualenv/ramabit/3.7/lib/python3.7/site-packages/django/views/decorators/csrf.py", line 54, in wrapped_view
    return view_func(*args, **kwargs)
  File "/home/ramabitc/virtualenv/ramabit/3.7/lib/python3.7/site-packages/django/views/generic/base.py", line 70, in view
    return self.dispatch(request, *args, **kwargs)
  File "/home/ramabitc/virtualenv/ramabit/3.7/lib/python3.7/site-packages/rest_framework/views.py", line 509, in dispatch
    response = self.handle_exception(exc)
  File "/home/ramabitc/virtualenv/ramabit/3.7/lib/python3.7/site-packages/rest_framework/views.py", line 469, in handle_exception
    self.raise_uncaught_exception(exc)
  File "/home/ramabitc/virtualenv/ramabit/3.7/lib/python3.7/site-packages/rest_framework/views.py", line 480, in raise_uncaught_exception
    raise exc
  File "/home/ramabitc/virtualenv/ramabit/3.7/lib/python3.7/site-packages/rest_framework/views.py", line 506, in dispatch
    response = handler(request, *args, **kwargs)
  File "/home/ramabitc/ramabit/api/views.py", line 40, in post
    user = User.objects.get(username = request.data['username'])
KeyError: 'username'
Internal Server Error: /api/v1/vorood
Traceback (most recent call last):
  File "/home/ramabitc/virtualenv/ramabit/3.7/lib/python3.7/site-packages/django/core/handlers/exception.py", line 47, in inner
    response = get_response(request)
  File "/home/ramabitc/virtualenv/ramabit/3.7/lib/python3.7/site-packages/django/core/handlers/base.py", line 181, in _get_response
    response = wrapped_callback(request, *callback_args, **callback_kwargs)
  File "/home/ramabitc/virtualenv/ramabit/3.7/lib/python3.7/site-packages/django/views/decorators/csrf.py", line 54, in wrapped_view
    return view_func(*args, **kwargs)
  File "/home/ramabitc/virtualenv/ramabit/3.7/lib/python3.7/site-packages/django/views/generic/base.py", line 70, in view
    return self.dispatch(request, *args, **kwargs)
  File "/home/ramabitc/virtualenv/ramabit/3.7/lib/python3.7/site-packages/rest_framework/views.py", line 509, in dispatch
    response = self.handle_exception(exc)
  File "/home/ramabitc/virtualenv/ramabit/3.7/lib/python3.7/site-packages/rest_framework/views.py", line 469, in handle_exception
    self.raise_uncaught_exception(exc)
  File "/home/ramabitc/virtualenv/ramabit/3.7/lib/python3.7/site-packages/rest_framework/views.py", line 480, in raise_uncaught_exception
    raise exc
  File "/home/ramabitc/virtualenv/ramabit/3.7/lib/python3.7/site-packages/rest_framework/views.py", line 506, in dispatch
    response = handler(request, *args, **kwargs)
  File "/home/ramabitc/ramabit/api/views.py", line 57, in post
    user = User.objects.get(username = request.data['username'])
  File "/home/ramabitc/virtualenv/ramabit/3.7/lib/python3.7/site-packages/django/db/models/manager.py", line 85, in manager_method
    return getattr(self.get_queryset(), name)(*args, **kwargs)
  File "/home/ramabitc/virtualenv/ramabit/3.7/lib/python3.7/site-packages/django/db/models/query.py", line 437, in get
    self.model._meta.object_name
auctions.models.User.DoesNotExist: User matching query does not exist.
Internal Server Error: /api/v1/inv
Traceback (most recent call last):
  File "/home/ramabitc/virtualenv/ramabit/3.7/lib/python3.7/site-packages/django/db/backends/utils.py", line 84, in _execute
    return self.cursor.execute(sql, params)
psycopg2.errors.SyntaxError: syntax error at or near "ON"
LINE 1: ...1" ("from_user_id", "to_user_id") VALUES (34, 46) ON CONFLIC...
                                                             ^


The above exception was the direct cause of the following exception:

Traceback (most recent call last):
  File "/home/ramabitc/virtualenv/ramabit/3.7/lib/python3.7/site-packages/django/core/handlers/exception.py", line 47, in inner
    response = get_response(request)
  File "/home/ramabitc/virtualenv/ramabit/3.7/lib/python3.7/site-packages/django/core/handlers/base.py", line 181, in _get_response
    response = wrapped_callback(request, *callback_args, **callback_kwargs)
  File "/home/ramabitc/virtualenv/ramabit/3.7/lib/python3.7/site-packages/django/views/decorators/csrf.py", line 54, in wrapped_view
    return view_func(*args, **kwargs)
  File "/home/ramabitc/virtualenv/ramabit/3.7/lib/python3.7/site-packages/django/views/generic/base.py", line 70, in view
    return self.dispatch(request, *args, **kwargs)
  File "/home/ramabitc/virtualenv/ramabit/3.7/lib/python3.7/site-packages/rest_framework/views.py", line 509, in dispatch
    response = self.handle_exception(exc)
  File "/home/ramabitc/virtualenv/ramabit/3.7/lib/python3.7/site-packages/rest_framework/views.py", line 469, in handle_exception
    self.raise_uncaught_exception(exc)
  File "/home/ramabitc/virtualenv/ramabit/3.7/lib/python3.7/site-packages/rest_framework/views.py", line 480, in raise_uncaught_exception
    raise exc
  File "/home/ramabitc/virtualenv/ramabit/3.7/lib/python3.7/site-packages/rest_framework/views.py", line 506, in dispatch
    response = handler(request, *args, **kwargs)
  File "/home/ramabitc/ramabit/api/views.py", line 44, in post
    user1.level1.add(*[user])
  File "/home/ramabitc/virtualenv/ramabit/3.7/lib/python3.7/site-packages/django/db/models/fields/related_descriptors.py", line 952, in add
    through_defaults=through_defaults,
  File "/home/ramabitc/virtualenv/ramabit/3.7/lib/python3.7/site-packages/django/db/models/fields/related_descriptors.py", line 1136, in _add_items
    ], ignore_conflicts=True)
  File "/home/ramabitc/virtualenv/ramabit/3.7/lib/python3.7/site-packages/django/db/models/query.py", line 515, in bulk_create
    objs_without_pk, fields, batch_size, ignore_conflicts=ignore_conflicts,
  File "/home/ramabitc/virtualenv/ramabit/3.7/lib/python3.7/site-packages/django/db/models/query.py", line 1293, in _batched_insert
    self._insert(item, fields=fields, using=self.db, ignore_conflicts=ignore_conflicts)
  File "/home/ramabitc/virtualenv/ramabit/3.7/lib/python3.7/site-packages/django/db/models/query.py", line 1270, in _insert
    return query.get_compiler(using=using).execute_sql(returning_fields)
  File "/home/ramabitc/virtualenv/ramabit/3.7/lib/python3.7/site-packages/django/db/models/sql/compiler.py", line 1416, in execute_sql
    cursor.execute(sql, params)
  File "/home/ramabitc/virtualenv/ramabit/3.7/lib/python3.7/site-packages/django/db/backends/utils.py", line 98, in execute
    return super().execute(sql, params)
  File "/home/ramabitc/virtualenv/ramabit/3.7/lib/python3.7/site-packages/django/db/backends/utils.py", line 66, in execute
    return self._execute_with_wrappers(sql, params, many=False, executor=self._execute)
  File "/home/ramabitc/virtualenv/ramabit/3.7/lib/python3.7/site-packages/django/db/backends/utils.py", line 75, in _execute_with_wrappers
    return executor(sql, params, many, context)
  File "/home/ramabitc/virtualenv/ramabit/3.7/lib/python3.7/site-packages/django/db/backends/utils.py", line 84, in _execute
    return self.cursor.execute(sql, params)
  File "/home/ramabitc/virtualenv/ramabit/3.7/lib/python3.7/site-packages/django/db/utils.py", line 90, in __exit__
    raise dj_exc_value.with_traceback(traceback) from exc_value
  File "/home/ramabitc/virtualenv/ramabit/3.7/lib/python3.7/site-packages/django/db/backends/utils.py", line 84, in _execute
    return self.cursor.execute(sql, params)
django.db.utils.ProgrammingError: syntax error at or near "ON"
LINE 1: ...1" ("from_user_id", "to_user_id") VALUES (34, 46) ON CONFLIC...
                                                             ^

Internal Server Error: /api/v1/inv
Traceback (most recent call last):
  File "/home/ramabitc/virtualenv/ramabit/3.7/lib/python3.7/site-packages/django/core/handlers/exception.py", line 47, in inner
    response = get_response(request)
  File "/home/ramabitc/virtualenv/ramabit/3.7/lib/python3.7/site-packages/django/core/handlers/base.py", line 181, in _get_response
    response = wrapped_callback(request, *callback_args, **callback_kwargs)
  File "/home/ramabitc/virtualenv/ramabit/3.7/lib/python3.7/site-packages/django/views/decorators/csrf.py", line 54, in wrapped_view
    return view_func(*args, **kwargs)
  File "/home/ramabitc/virtualenv/ramabit/3.7/lib/python3.7/site-packages/django/views/generic/base.py", line 70, in view
    return self.dispatch(request, *args, **kwargs)
  File "/home/ramabitc/virtualenv/ramabit/3.7/lib/python3.7/site-packages/rest_framework/views.py", line 509, in dispatch
    response = self.handle_exception(exc)
  File "/home/ramabitc/virtualenv/ramabit/3.7/lib/python3.7/site-packages/rest_framework/views.py", line 469, in handle_exception
    self.raise_uncaught_exception(exc)
  File "/home/ramabitc/virtualenv/ramabit/3.7/lib/python3.7/site-packages/rest_framework/views.py", line 480, in raise_uncaught_exception
    raise exc
  File "/home/ramabitc/virtualenv/ramabit/3.7/lib/python3.7/site-packages/rest_framework/views.py", line 506, in dispatch
    response = handler(request, *args, **kwargs)
  File "/home/ramabitc/ramabit/api/views.py", line 40, in post
    user = User.objects.get(username = request.data['username'])
KeyError: 'username'
Internal Server Error: /api/v1/inv
Traceback (most recent call last):
  File "/home/ramabitc/virtualenv/ramabit/3.7/lib/python3.7/site-packages/django/core/handlers/exception.py", line 47, in inner
    response = get_response(request)
  File "/home/ramabitc/virtualenv/ramabit/3.7/lib/python3.7/site-packages/django/core/handlers/base.py", line 181, in _get_response
    response = wrapped_callback(request, *callback_args, **callback_kwargs)
  File "/home/ramabitc/virtualenv/ramabit/3.7/lib/python3.7/site-packages/django/views/decorators/csrf.py", line 54, in wrapped_view
    return view_func(*args, **kwargs)
  File "/home/ramabitc/virtualenv/ramabit/3.7/lib/python3.7/site-packages/django/views/generic/base.py", line 70, in view
    return self.dispatch(request, *args, **kwargs)
  File "/home/ramabitc/virtualenv/ramabit/3.7/lib/python3.7/site-packages/rest_framework/views.py", line 509, in dispatch
    response = self.handle_exception(exc)
  File "/home/ramabitc/virtualenv/ramabit/3.7/lib/python3.7/site-packages/rest_framework/views.py", line 469, in handle_exception
    self.raise_uncaught_exception(exc)
  File "/home/ramabitc/virtualenv/ramabit/3.7/lib/python3.7/site-packages/rest_framework/views.py", line 480, in raise_uncaught_exception
    raise exc
  File "/home/ramabitc/virtualenv/ramabit/3.7/lib/python3.7/site-packages/rest_framework/views.py", line 506, in dispatch
    response = handler(request, *args, **kwargs)
  File "/home/ramabitc/ramabit/api/views.py", line 40, in post
    user = User.objects.get(username = request.data['username'])
KeyError: 'username'
Internal Server Error: /api/v1/inv
Traceback (most recent call last):
  File "/home/ramabitc/virtualenv/ramabit/3.7/lib/python3.7/site-packages/django/core/handlers/exception.py", line 47, in inner
    response = get_response(request)
  File "/home/ramabitc/virtualenv/ramabit/3.7/lib/python3.7/site-packages/django/core/handlers/base.py", line 181, in _get_response
    response = wrapped_callback(request, *callback_args, **callback_kwargs)
  File "/home/ramabitc/virtualenv/ramabit/3.7/lib/python3.7/site-packages/django/views/decorators/csrf.py", line 54, in wrapped_view
    return view_func(*args, **kwargs)
  File "/home/ramabitc/virtualenv/ramabit/3.7/lib/python3.7/site-packages/django/views/generic/base.py", line 70, in view
    return self.dispatch(request, *args, **kwargs)
  File "/home/ramabitc/virtualenv/ramabit/3.7/lib/python3.7/site-packages/rest_framework/views.py", line 509, in dispatch
    response = self.handle_exception(exc)
  File "/home/ramabitc/virtualenv/ramabit/3.7/lib/python3.7/site-packages/rest_framework/views.py", line 469, in handle_exception
    self.raise_uncaught_exception(exc)
  File "/home/ramabitc/virtualenv/ramabit/3.7/lib/python3.7/site-packages/rest_framework/views.py", line 480, in raise_uncaught_exception
    raise exc
  File "/home/ramabitc/virtualenv/ramabit/3.7/lib/python3.7/site-packages/rest_framework/views.py", line 506, in dispatch
    response = handler(request, *args, **kwargs)
  File "/home/ramabitc/ramabit/api/views.py", line 40, in post
    user = User.objects.get(username = request.data['username'])
KeyError: 'username'
Internal Server Error: /api/v1/inv
Traceback (most recent call last):
  File "/home/ramabitc/virtualenv/ramabit/3.7/lib/python3.7/site-packages/django/core/handlers/exception.py", line 47, in inner
    response = get_response(request)
  File "/home/ramabitc/virtualenv/ramabit/3.7/lib/python3.7/site-packages/django/core/handlers/base.py", line 181, in _get_response
    response = wrapped_callback(request, *callback_args, **callback_kwargs)
  File "/home/ramabitc/virtualenv/ramabit/3.7/lib/python3.7/site-packages/django/views/decorators/csrf.py", line 54, in wrapped_view
    return view_func(*args, **kwargs)
  File "/home/ramabitc/virtualenv/ramabit/3.7/lib/python3.7/site-packages/django/views/generic/base.py", line 70, in view
    return self.dispatch(request, *args, **kwargs)
  File "/home/ramabitc/virtualenv/ramabit/3.7/lib/python3.7/site-packages/rest_framework/views.py", line 509, in dispatch
    response = self.handle_exception(exc)
  File "/home/ramabitc/virtualenv/ramabit/3.7/lib/python3.7/site-packages/rest_framework/views.py", line 469, in handle_exception
    self.raise_uncaught_exception(exc)
  File "/home/ramabitc/virtualenv/ramabit/3.7/lib/python3.7/site-packages/rest_framework/views.py", line 480, in raise_uncaught_exception
    raise exc
  File "/home/ramabitc/virtualenv/ramabit/3.7/lib/python3.7/site-packages/rest_framework/views.py", line 506, in dispatch
    response = handler(request, *args, **kwargs)
  File "/home/ramabitc/ramabit/api/views.py", line 40, in post
    user = User.objects.get(username = request.data['username'])
KeyError: 'username'
Internal Server Error: /api/v1/inv
Traceback (most recent call last):
  File "/home/ramabitc/virtualenv/ramabit/3.7/lib/python3.7/site-packages/django/core/handlers/exception.py", line 47, in inner
    response = get_response(request)
  File "/home/ramabitc/virtualenv/ramabit/3.7/lib/python3.7/site-packages/django/core/handlers/base.py", line 181, in _get_response
    response = wrapped_callback(request, *callback_args, **callback_kwargs)
  File "/home/ramabitc/virtualenv/ramabit/3.7/lib/python3.7/site-packages/django/views/decorators/csrf.py", line 54, in wrapped_view
    return view_func(*args, **kwargs)
  File "/home/ramabitc/virtualenv/ramabit/3.7/lib/python3.7/site-packages/django/views/generic/base.py", line 70, in view
    return self.dispatch(request, *args, **kwargs)
  File "/home/ramabitc/virtualenv/ramabit/3.7/lib/python3.7/site-packages/rest_framework/views.py", line 509, in dispatch
    response = self.handle_exception(exc)
  File "/home/ramabitc/virtualenv/ramabit/3.7/lib/python3.7/site-packages/rest_framework/views.py", line 469, in handle_exception
    self.raise_uncaught_exception(exc)
  File "/home/ramabitc/virtualenv/ramabit/3.7/lib/python3.7/site-packages/rest_framework/views.py", line 480, in raise_uncaught_exception
    raise exc
  File "/home/ramabitc/virtualenv/ramabit/3.7/lib/python3.7/site-packages/rest_framework/views.py", line 506, in dispatch
    response = handler(request, *args, **kwargs)
  File "/home/ramabitc/ramabit/api/views.py", line 40, in post
    user = User.objects.get(username = request.data['username'])
KeyError: 'username'
Internal Server Error: /api/v1/inv
Traceback (most recent call last):
  File "/home/ramabitc/virtualenv/ramabit/3.7/lib/python3.7/site-packages/django/core/handlers/exception.py", line 47, in inner
    response = get_response(request)
  File "/home/ramabitc/virtualenv/ramabit/3.7/lib/python3.7/site-packages/django/core/handlers/base.py", line 181, in _get_response
    response = wrapped_callback(request, *callback_args, **callback_kwargs)
  File "/home/ramabitc/virtualenv/ramabit/3.7/lib/python3.7/site-packages/django/views/decorators/csrf.py", line 54, in wrapped_view
    return view_func(*args, **kwargs)
  File "/home/ramabitc/virtualenv/ramabit/3.7/lib/python3.7/site-packages/django/views/generic/base.py", line 70, in view
    return self.dispatch(request, *args, **kwargs)
  File "/home/ramabitc/virtualenv/ramabit/3.7/lib/python3.7/site-packages/rest_framework/views.py", line 509, in dispatch
    response = self.handle_exception(exc)
  File "/home/ramabitc/virtualenv/ramabit/3.7/lib/python3.7/site-packages/rest_framework/views.py", line 469, in handle_exception
    self.raise_uncaught_exception(exc)
  File "/home/ramabitc/virtualenv/ramabit/3.7/lib/python3.7/site-packages/rest_framework/views.py", line 480, in raise_uncaught_exception
    raise exc
  File "/home/ramabitc/virtualenv/ramabit/3.7/lib/python3.7/site-packages/rest_framework/views.py", line 506, in dispatch
    response = handler(request, *args, **kwargs)
  File "/home/ramabitc/ramabit/api/views.py", line 40, in post
    user = User.objects.get(username = request.data['username'])
KeyError: 'username'
Internal Server Error: /api/v1/inv
Traceback (most recent call last):
  File "/home/ramabitc/virtualenv/ramabit/3.7/lib/python3.7/site-packages/django/core/handlers/exception.py", line 47, in inner
    response = get_response(request)
  File "/home/ramabitc/virtualenv/ramabit/3.7/lib/python3.7/site-packages/django/core/handlers/base.py", line 181, in _get_response
    response = wrapped_callback(request, *callback_args, **callback_kwargs)
  File "/home/ramabitc/virtualenv/ramabit/3.7/lib/python3.7/site-packages/django/views/decorators/csrf.py", line 54, in wrapped_view
    return view_func(*args, **kwargs)
  File "/home/ramabitc/virtualenv/ramabit/3.7/lib/python3.7/site-packages/django/views/generic/base.py", line 70, in view
    return self.dispatch(request, *args, **kwargs)
  File "/home/ramabitc/virtualenv/ramabit/3.7/lib/python3.7/site-packages/rest_framework/views.py", line 509, in dispatch
    response = self.handle_exception(exc)
  File "/home/ramabitc/virtualenv/ramabit/3.7/lib/python3.7/site-packages/rest_framework/views.py", line 469, in handle_exception
    self.raise_uncaught_exception(exc)
  File "/home/ramabitc/virtualenv/ramabit/3.7/lib/python3.7/site-packages/rest_framework/views.py", line 480, in raise_uncaught_exception
    raise exc
  File "/home/ramabitc/virtualenv/ramabit/3.7/lib/python3.7/site-packages/rest_framework/views.py", line 506, in dispatch
    response = handler(request, *args, **kwargs)
  File "/home/ramabitc/ramabit/api/views.py", line 40, in post
    user = User.objects.get(username = request.data['username'])
KeyError: 'username'
Internal Server Error: /api/v1/vorood
Traceback (most recent call last):
  File "/home/ramabitc/virtualenv/ramabit/3.7/lib/python3.7/site-packages/django/core/handlers/exception.py", line 47, in inner
    response = get_response(request)
  File "/home/ramabitc/virtualenv/ramabit/3.7/lib/python3.7/site-packages/django/core/handlers/base.py", line 181, in _get_response
    response = wrapped_callback(request, *callback_args, **callback_kwargs)
  File "/home/ramabitc/virtualenv/ramabit/3.7/lib/python3.7/site-packages/django/views/decorators/csrf.py", line 54, in wrapped_view
    return view_func(*args, **kwargs)
  File "/home/ramabitc/virtualenv/ramabit/3.7/lib/python3.7/site-packages/django/views/generic/base.py", line 70, in view
    return self.dispatch(request, *args, **kwargs)
  File "/home/ramabitc/virtualenv/ramabit/3.7/lib/python3.7/site-packages/rest_framework/views.py", line 509, in dispatch
    response = self.handle_exception(exc)
  File "/home/ramabitc/virtualenv/ramabit/3.7/lib/python3.7/site-packages/rest_framework/views.py", line 469, in handle_exception
    self.raise_uncaught_exception(exc)
  File "/home/ramabitc/virtualenv/ramabit/3.7/lib/python3.7/site-packages/rest_framework/views.py", line 480, in raise_uncaught_exception
    raise exc
  File "/home/ramabitc/virtualenv/ramabit/3.7/lib/python3.7/site-packages/rest_framework/views.py", line 506, in dispatch
    response = handler(request, *args, **kwargs)
  File "/home/ramabitc/ramabit/api/views.py", line 57, in post
    user = User.objects.get(username = request.data['username'])
  File "/home/ramabitc/virtualenv/ramabit/3.7/lib/python3.7/site-packages/django/db/models/manager.py", line 85, in manager_method
    return getattr(self.get_queryset(), name)(*args, **kwargs)
  File "/home/ramabitc/virtualenv/ramabit/3.7/lib/python3.7/site-packages/django/db/models/query.py", line 437, in get
    self.model._meta.object_name
auctions.models.User.DoesNotExist: User matching query does not exist.
Internal Server Error: /api/v1/inv
Traceback (most recent call last):
  File "/home/ramabitc/virtualenv/ramabit/3.7/lib/python3.7/site-packages/django/core/handlers/exception.py", line 47, in inner
    response = get_response(request)
  File "/home/ramabitc/virtualenv/ramabit/3.7/lib/python3.7/site-packages/django/core/handlers/base.py", line 181, in _get_response
    response = wrapped_callback(request, *callback_args, **callback_kwargs)
  File "/home/ramabitc/virtualenv/ramabit/3.7/lib/python3.7/site-packages/django/views/decorators/csrf.py", line 54, in wrapped_view
    return view_func(*args, **kwargs)
  File "/home/ramabitc/virtualenv/ramabit/3.7/lib/python3.7/site-packages/django/views/generic/base.py", line 70, in view
    return self.dispatch(request, *args, **kwargs)
  File "/home/ramabitc/virtualenv/ramabit/3.7/lib/python3.7/site-packages/rest_framework/views.py", line 509, in dispatch
    response = self.handle_exception(exc)
  File "/home/ramabitc/virtualenv/ramabit/3.7/lib/python3.7/site-packages/rest_framework/views.py", line 469, in handle_exception
    self.raise_uncaught_exception(exc)
  File "/home/ramabitc/virtualenv/ramabit/3.7/lib/python3.7/site-packages/rest_framework/views.py", line 480, in raise_uncaught_exception
    raise exc
  File "/home/ramabitc/virtualenv/ramabit/3.7/lib/python3.7/site-packages/rest_framework/views.py", line 506, in dispatch
    response = handler(request, *args, **kwargs)
  File "/home/ramabitc/ramabit/api/views.py", line 40, in post
    user = User.objects.get(username = request.data['username'])
KeyError: 'username'
Internal Server Error: /api/v1/inv
Traceback (most recent call last):
  File "/home/ramabitc/virtualenv/ramabit/3.7/lib/python3.7/site-packages/django/core/handlers/exception.py", line 47, in inner
    response = get_response(request)
  File "/home/ramabitc/virtualenv/ramabit/3.7/lib/python3.7/site-packages/django/core/handlers/base.py", line 181, in _get_response
    response = wrapped_callback(request, *callback_args, **callback_kwargs)
  File "/home/ramabitc/virtualenv/ramabit/3.7/lib/python3.7/site-packages/django/views/decorators/csrf.py", line 54, in wrapped_view
    return view_func(*args, **kwargs)
  File "/home/ramabitc/virtualenv/ramabit/3.7/lib/python3.7/site-packages/django/views/generic/base.py", line 70, in view
    return self.dispatch(request, *args, **kwargs)
  File "/home/ramabitc/virtualenv/ramabit/3.7/lib/python3.7/site-packages/rest_framework/views.py", line 509, in dispatch
    response = self.handle_exception(exc)
  File "/home/ramabitc/virtualenv/ramabit/3.7/lib/python3.7/site-packages/rest_framework/views.py", line 469, in handle_exception
    self.raise_uncaught_exception(exc)
  File "/home/ramabitc/virtualenv/ramabit/3.7/lib/python3.7/site-packages/rest_framework/views.py", line 480, in raise_uncaught_exception
    raise exc
  File "/home/ramabitc/virtualenv/ramabit/3.7/lib/python3.7/site-packages/rest_framework/views.py", line 506, in dispatch
    response = handler(request, *args, **kwargs)
  File "/home/ramabitc/ramabit/api/views.py", line 40, in post
    user = User.objects.get(username = request.data['username'])
KeyError: 'username'
Internal Server Error: /api/v1/inv
Traceback (most recent call last):
  File "/home/ramabitc/virtualenv/ramabit/3.7/lib/python3.7/site-packages/django/core/handlers/exception.py", line 47, in inner
    response = get_response(request)
  File "/home/ramabitc/virtualenv/ramabit/3.7/lib/python3.7/site-packages/django/core/handlers/base.py", line 181, in _get_response
    response = wrapped_callback(request, *callback_args, **callback_kwargs)
  File "/home/ramabitc/virtualenv/ramabit/3.7/lib/python3.7/site-packages/django/views/decorators/csrf.py", line 54, in wrapped_view
    return view_func(*args, **kwargs)
  File "/home/ramabitc/virtualenv/ramabit/3.7/lib/python3.7/site-packages/django/views/generic/base.py", line 70, in view
    return self.dispatch(request, *args, **kwargs)
  File "/home/ramabitc/virtualenv/ramabit/3.7/lib/python3.7/site-packages/rest_framework/views.py", line 509, in dispatch
    response = self.handle_exception(exc)
  File "/home/ramabitc/virtualenv/ramabit/3.7/lib/python3.7/site-packages/rest_framework/views.py", line 469, in handle_exception
    self.raise_uncaught_exception(exc)
  File "/home/ramabitc/virtualenv/ramabit/3.7/lib/python3.7/site-packages/rest_framework/views.py", line 480, in raise_uncaught_exception
    raise exc
  File "/home/ramabitc/virtualenv/ramabit/3.7/lib/python3.7/site-packages/rest_framework/views.py", line 506, in dispatch
    response = handler(request, *args, **kwargs)
  File "/home/ramabitc/ramabit/api/views.py", line 40, in post
    user = User.objects.get(username = request.data['username'])
KeyError: 'username'
Internal Server Error: /api/v1/inv
Traceback (most recent call last):
  File "/home/ramabitc/virtualenv/ramabit/3.7/lib/python3.7/site-packages/django/core/handlers/exception.py", line 47, in inner
    response = get_response(request)
  File "/home/ramabitc/virtualenv/ramabit/3.7/lib/python3.7/site-packages/django/core/handlers/base.py", line 181, in _get_response
    response = wrapped_callback(request, *callback_args, **callback_kwargs)
  File "/home/ramabitc/virtualenv/ramabit/3.7/lib/python3.7/site-packages/django/views/decorators/csrf.py", line 54, in wrapped_view
    return view_func(*args, **kwargs)
  File "/home/ramabitc/virtualenv/ramabit/3.7/lib/python3.7/site-packages/django/views/generic/base.py", line 70, in view
    return self.dispatch(request, *args, **kwargs)
  File "/home/ramabitc/virtualenv/ramabit/3.7/lib/python3.7/site-packages/rest_framework/views.py", line 509, in dispatch
    response = self.handle_exception(exc)
  File "/home/ramabitc/virtualenv/ramabit/3.7/lib/python3.7/site-packages/rest_framework/views.py", line 469, in handle_exception
    self.raise_uncaught_exception(exc)
  File "/home/ramabitc/virtualenv/ramabit/3.7/lib/python3.7/site-packages/rest_framework/views.py", line 480, in raise_uncaught_exception
    raise exc
  File "/home/ramabitc/virtualenv/ramabit/3.7/lib/python3.7/site-packages/rest_framework/views.py", line 506, in dispatch
    response = handler(request, *args, **kwargs)
  File "/home/ramabitc/ramabit/api/views.py", line 40, in post
    user = User.objects.get(username = request.data['username'])
KeyError: 'username'
Internal Server Error: /api/v1/inv
Traceback (most recent call last):
  File "/home/ramabitc/virtualenv/ramabit/3.7/lib/python3.7/site-packages/django/core/handlers/exception.py", line 47, in inner
    response = get_response(request)
  File "/home/ramabitc/virtualenv/ramabit/3.7/lib/python3.7/site-packages/django/core/handlers/base.py", line 181, in _get_response
    response = wrapped_callback(request, *callback_args, **callback_kwargs)
  File "/home/ramabitc/virtualenv/ramabit/3.7/lib/python3.7/site-packages/django/views/decorators/csrf.py", line 54, in wrapped_view
    return view_func(*args, **kwargs)
  File "/home/ramabitc/virtualenv/ramabit/3.7/lib/python3.7/site-packages/django/views/generic/base.py", line 70, in view
    return self.dispatch(request, *args, **kwargs)
  File "/home/ramabitc/virtualenv/ramabit/3.7/lib/python3.7/site-packages/rest_framework/views.py", line 509, in dispatch
    response = self.handle_exception(exc)
  File "/home/ramabitc/virtualenv/ramabit/3.7/lib/python3.7/site-packages/rest_framework/views.py", line 469, in handle_exception
    self.raise_uncaught_exception(exc)
  File "/home/ramabitc/virtualenv/ramabit/3.7/lib/python3.7/site-packages/rest_framework/views.py", line 480, in raise_uncaught_exception
    raise exc
  File "/home/ramabitc/virtualenv/ramabit/3.7/lib/python3.7/site-packages/rest_framework/views.py", line 506, in dispatch
    response = handler(request, *args, **kwargs)
  File "/home/ramabitc/ramabit/api/views.py", line 40, in post
    user = User.objects.get(username = request.data['username'])
KeyError: 'username'
Internal Server Error: /api/v1/inv
Traceback (most recent call last):
  File "/home/ramabitc/virtualenv/ramabit/3.7/lib/python3.7/site-packages/django/core/handlers/exception.py", line 47, in inner
    response = get_response(request)
  File "/home/ramabitc/virtualenv/ramabit/3.7/lib/python3.7/site-packages/django/core/handlers/base.py", line 181, in _get_response
    response = wrapped_callback(request, *callback_args, **callback_kwargs)
  File "/home/ramabitc/virtualenv/ramabit/3.7/lib/python3.7/site-packages/django/views/decorators/csrf.py", line 54, in wrapped_view
    return view_func(*args, **kwargs)
  File "/home/ramabitc/virtualenv/ramabit/3.7/lib/python3.7/site-packages/django/views/generic/base.py", line 70, in view
    return self.dispatch(request, *args, **kwargs)
  File "/home/ramabitc/virtualenv/ramabit/3.7/lib/python3.7/site-packages/rest_framework/views.py", line 509, in dispatch
    response = self.handle_exception(exc)
  File "/home/ramabitc/virtualenv/ramabit/3.7/lib/python3.7/site-packages/rest_framework/views.py", line 469, in handle_exception
    self.raise_uncaught_exception(exc)
  File "/home/ramabitc/virtualenv/ramabit/3.7/lib/python3.7/site-packages/rest_framework/views.py", line 480, in raise_uncaught_exception
    raise exc
  File "/home/ramabitc/virtualenv/ramabit/3.7/lib/python3.7/site-packages/rest_framework/views.py", line 506, in dispatch
    response = handler(request, *args, **kwargs)
  File "/home/ramabitc/ramabit/api/views.py", line 40, in post
    user = User.objects.get(username = request.data['username'])
KeyError: 'username'
Internal Server Error: /api/v1/inv
Traceback (most recent call last):
  File "/home/ramabitc/virtualenv/ramabit/3.7/lib/python3.7/site-packages/django/core/handlers/exception.py", line 47, in inner
    response = get_response(request)
  File "/home/ramabitc/virtualenv/ramabit/3.7/lib/python3.7/site-packages/django/core/handlers/base.py", line 181, in _get_response
    response = wrapped_callback(request, *callback_args, **callback_kwargs)
  File "/home/ramabitc/virtualenv/ramabit/3.7/lib/python3.7/site-packages/django/views/decorators/csrf.py", line 54, in wrapped_view
    return view_func(*args, **kwargs)
  File "/home/ramabitc/virtualenv/ramabit/3.7/lib/python3.7/site-packages/django/views/generic/base.py", line 70, in view
    return self.dispatch(request, *args, **kwargs)
  File "/home/ramabitc/virtualenv/ramabit/3.7/lib/python3.7/site-packages/rest_framework/views.py", line 509, in dispatch
    response = self.handle_exception(exc)
  File "/home/ramabitc/virtualenv/ramabit/3.7/lib/python3.7/site-packages/rest_framework/views.py", line 469, in handle_exception
    self.raise_uncaught_exception(exc)
  File "/home/ramabitc/virtualenv/ramabit/3.7/lib/python3.7/site-packages/rest_framework/views.py", line 480, in raise_uncaught_exception
    raise exc
  File "/home/ramabitc/virtualenv/ramabit/3.7/lib/python3.7/site-packages/rest_framework/views.py", line 506, in dispatch
    response = handler(request, *args, **kwargs)
  File "/home/ramabitc/ramabit/api/views.py", line 40, in post
    user = User.objects.get(username = request.data['username'])
KeyError: 'username'
Internal Server Error: /api/v1/vorood
Traceback (most recent call last):
  File "/home/ramabitc/virtualenv/ramabit/3.7/lib/python3.7/site-packages/django/core/handlers/exception.py", line 47, in inner
    response = get_response(request)
  File "/home/ramabitc/virtualenv/ramabit/3.7/lib/python3.7/site-packages/django/core/handlers/base.py", line 181, in _get_response
    response = wrapped_callback(request, *callback_args, **callback_kwargs)
  File "/home/ramabitc/virtualenv/ramabit/3.7/lib/python3.7/site-packages/django/views/decorators/csrf.py", line 54, in wrapped_view
    return view_func(*args, **kwargs)
  File "/home/ramabitc/virtualenv/ramabit/3.7/lib/python3.7/site-packages/django/views/generic/base.py", line 70, in view
    return self.dispatch(request, *args, **kwargs)
  File "/home/ramabitc/virtualenv/ramabit/3.7/lib/python3.7/site-packages/rest_framework/views.py", line 509, in dispatch
    response = self.handle_exception(exc)
  File "/home/ramabitc/virtualenv/ramabit/3.7/lib/python3.7/site-packages/rest_framework/views.py", line 469, in handle_exception
    self.raise_uncaught_exception(exc)
  File "/home/ramabitc/virtualenv/ramabit/3.7/lib/python3.7/site-packages/rest_framework/views.py", line 480, in raise_uncaught_exception
    raise exc
  File "/home/ramabitc/virtualenv/ramabit/3.7/lib/python3.7/site-packages/rest_framework/views.py", line 506, in dispatch
    response = handler(request, *args, **kwargs)
  File "/home/ramabitc/ramabit/api/views.py", line 57, in post
    user = User.objects.get(username = request.data['username'])
  File "/home/ramabitc/virtualenv/ramabit/3.7/lib/python3.7/site-packages/django/db/models/manager.py", line 85, in manager_method
    return getattr(self.get_queryset(), name)(*args, **kwargs)
  File "/home/ramabitc/virtualenv/ramabit/3.7/lib/python3.7/site-packages/django/db/models/query.py", line 437, in get
    self.model._meta.object_name
auctions.models.User.DoesNotExist: User matching query does not exist.
Internal Server Error: /api/v1/inv
Traceback (most recent call last):
  File "/home/ramabitc/virtualenv/ramabit/3.7/lib/python3.7/site-packages/django/core/handlers/exception.py", line 47, in inner
    response = get_response(request)
  File "/home/ramabitc/virtualenv/ramabit/3.7/lib/python3.7/site-packages/django/core/handlers/base.py", line 181, in _get_response
    response = wrapped_callback(request, *callback_args, **callback_kwargs)
  File "/home/ramabitc/virtualenv/ramabit/3.7/lib/python3.7/site-packages/django/views/decorators/csrf.py", line 54, in wrapped_view
    return view_func(*args, **kwargs)
  File "/home/ramabitc/virtualenv/ramabit/3.7/lib/python3.7/site-packages/django/views/generic/base.py", line 70, in view
    return self.dispatch(request, *args, **kwargs)
  File "/home/ramabitc/virtualenv/ramabit/3.7/lib/python3.7/site-packages/rest_framework/views.py", line 509, in dispatch
    response = self.handle_exception(exc)
  File "/home/ramabitc/virtualenv/ramabit/3.7/lib/python3.7/site-packages/rest_framework/views.py", line 469, in handle_exception
    self.raise_uncaught_exception(exc)
  File "/home/ramabitc/virtualenv/ramabit/3.7/lib/python3.7/site-packages/rest_framework/views.py", line 480, in raise_uncaught_exception
    raise exc
  File "/home/ramabitc/virtualenv/ramabit/3.7/lib/python3.7/site-packages/rest_framework/views.py", line 506, in dispatch
    response = handler(request, *args, **kwargs)
  File "/home/ramabitc/ramabit/api/views.py", line 40, in post
    user = User.objects.get(username = request.data['username'])
KeyError: 'username'
Internal Server Error: /api/v1/inv
Traceback (most recent call last):
  File "/home/ramabitc/virtualenv/ramabit/3.7/lib/python3.7/site-packages/django/core/handlers/exception.py", line 47, in inner
    response = get_response(request)
  File "/home/ramabitc/virtualenv/ramabit/3.7/lib/python3.7/site-packages/django/core/handlers/base.py", line 181, in _get_response
    response = wrapped_callback(request, *callback_args, **callback_kwargs)
  File "/home/ramabitc/virtualenv/ramabit/3.7/lib/python3.7/site-packages/django/views/decorators/csrf.py", line 54, in wrapped_view
    return view_func(*args, **kwargs)
  File "/home/ramabitc/virtualenv/ramabit/3.7/lib/python3.7/site-packages/django/views/generic/base.py", line 70, in view
    return self.dispatch(request, *args, **kwargs)
  File "/home/ramabitc/virtualenv/ramabit/3.7/lib/python3.7/site-packages/rest_framework/views.py", line 509, in dispatch
    response = self.handle_exception(exc)
  File "/home/ramabitc/virtualenv/ramabit/3.7/lib/python3.7/site-packages/rest_framework/views.py", line 469, in handle_exception
    self.raise_uncaught_exception(exc)
  File "/home/ramabitc/virtualenv/ramabit/3.7/lib/python3.7/site-packages/rest_framework/views.py", line 480, in raise_uncaught_exception
    raise exc
  File "/home/ramabitc/virtualenv/ramabit/3.7/lib/python3.7/site-packages/rest_framework/views.py", line 506, in dispatch
    response = handler(request, *args, **kwargs)
  File "/home/ramabitc/ramabit/api/views.py", line 40, in post
    user = User.objects.get(username = request.data['username'])
KeyError: 'username'
Internal Server Error: /api/v1/inv
Traceback (most recent call last):
  File "/home/ramabitc/virtualenv/ramabit/3.7/lib/python3.7/site-packages/django/core/handlers/exception.py", line 47, in inner
    response = get_response(request)
  File "/home/ramabitc/virtualenv/ramabit/3.7/lib/python3.7/site-packages/django/core/handlers/base.py", line 181, in _get_response
    response = wrapped_callback(request, *callback_args, **callback_kwargs)
  File "/home/ramabitc/virtualenv/ramabit/3.7/lib/python3.7/site-packages/django/views/decorators/csrf.py", line 54, in wrapped_view
    return view_func(*args, **kwargs)
  File "/home/ramabitc/virtualenv/ramabit/3.7/lib/python3.7/site-packages/django/views/generic/base.py", line 70, in view
    return self.dispatch(request, *args, **kwargs)
  File "/home/ramabitc/virtualenv/ramabit/3.7/lib/python3.7/site-packages/rest_framework/views.py", line 509, in dispatch
    response = self.handle_exception(exc)
  File "/home/ramabitc/virtualenv/ramabit/3.7/lib/python3.7/site-packages/rest_framework/views.py", line 469, in handle_exception
    self.raise_uncaught_exception(exc)
  File "/home/ramabitc/virtualenv/ramabit/3.7/lib/python3.7/site-packages/rest_framework/views.py", line 480, in raise_uncaught_exception
    raise exc
  File "/home/ramabitc/virtualenv/ramabit/3.7/lib/python3.7/site-packages/rest_framework/views.py", line 506, in dispatch
    response = handler(request, *args, **kwargs)
  File "/home/ramabitc/ramabit/api/views.py", line 40, in post
    user = User.objects.get(username = request.data['username'])
KeyError: 'username'
Internal Server Error: /api/v1/inv
Traceback (most recent call last):
  File "/home/ramabitc/virtualenv/ramabit/3.7/lib/python3.7/site-packages/django/core/handlers/exception.py", line 47, in inner
    response = get_response(request)
  File "/home/ramabitc/virtualenv/ramabit/3.7/lib/python3.7/site-packages/django/core/handlers/base.py", line 181, in _get_response
    response = wrapped_callback(request, *callback_args, **callback_kwargs)
  File "/home/ramabitc/virtualenv/ramabit/3.7/lib/python3.7/site-packages/django/views/decorators/csrf.py", line 54, in wrapped_view
    return view_func(*args, **kwargs)
  File "/home/ramabitc/virtualenv/ramabit/3.7/lib/python3.7/site-packages/django/views/generic/base.py", line 70, in view
    return self.dispatch(request, *args, **kwargs)
  File "/home/ramabitc/virtualenv/ramabit/3.7/lib/python3.7/site-packages/rest_framework/views.py", line 509, in dispatch
    response = self.handle_exception(exc)
  File "/home/ramabitc/virtualenv/ramabit/3.7/lib/python3.7/site-packages/rest_framework/views.py", line 469, in handle_exception
    self.raise_uncaught_exception(exc)
  File "/home/ramabitc/virtualenv/ramabit/3.7/lib/python3.7/site-packages/rest_framework/views.py", line 480, in raise_uncaught_exception
    raise exc
  File "/home/ramabitc/virtualenv/ramabit/3.7/lib/python3.7/site-packages/rest_framework/views.py", line 506, in dispatch
    response = handler(request, *args, **kwargs)
  File "/home/ramabitc/ramabit/api/views.py", line 40, in post
    user = User.objects.get(username = request.data['username'])
KeyError: 'username'
Internal Server Error: /api/v1/inv
Traceback (most recent call last):
  File "/home/ramabitc/virtualenv/ramabit/3.7/lib/python3.7/site-packages/django/core/handlers/exception.py", line 47, in inner
    response = get_response(request)
  File "/home/ramabitc/virtualenv/ramabit/3.7/lib/python3.7/site-packages/django/core/handlers/base.py", line 181, in _get_response
    response = wrapped_callback(request, *callback_args, **callback_kwargs)
  File "/home/ramabitc/virtualenv/ramabit/3.7/lib/python3.7/site-packages/django/views/decorators/csrf.py", line 54, in wrapped_view
    return view_func(*args, **kwargs)
  File "/home/ramabitc/virtualenv/ramabit/3.7/lib/python3.7/site-packages/django/views/generic/base.py", line 70, in view
    return self.dispatch(request, *args, **kwargs)
  File "/home/ramabitc/virtualenv/ramabit/3.7/lib/python3.7/site-packages/rest_framework/views.py", line 509, in dispatch
    response = self.handle_exception(exc)
  File "/home/ramabitc/virtualenv/ramabit/3.7/lib/python3.7/site-packages/rest_framework/views.py", line 469, in handle_exception
    self.raise_uncaught_exception(exc)
  File "/home/ramabitc/virtualenv/ramabit/3.7/lib/python3.7/site-packages/rest_framework/views.py", line 480, in raise_uncaught_exception
    raise exc
  File "/home/ramabitc/virtualenv/ramabit/3.7/lib/python3.7/site-packages/rest_framework/views.py", line 506, in dispatch
    response = handler(request, *args, **kwargs)
  File "/home/ramabitc/ramabit/api/views.py", line 40, in post
    user = User.objects.get(username = request.data['username'])
KeyError: 'username'
Internal Server Error: /api/v1/inv
Traceback (most recent call last):
  File "/home/ramabitc/virtualenv/ramabit/3.7/lib/python3.7/site-packages/django/core/handlers/exception.py", line 47, in inner
    response = get_response(request)
  File "/home/ramabitc/virtualenv/ramabit/3.7/lib/python3.7/site-packages/django/core/handlers/base.py", line 181, in _get_response
    response = wrapped_callback(request, *callback_args, **callback_kwargs)
  File "/home/ramabitc/virtualenv/ramabit/3.7/lib/python3.7/site-packages/django/views/decorators/csrf.py", line 54, in wrapped_view
    return view_func(*args, **kwargs)
  File "/home/ramabitc/virtualenv/ramabit/3.7/lib/python3.7/site-packages/django/views/generic/base.py", line 70, in view
    return self.dispatch(request, *args, **kwargs)
  File "/home/ramabitc/virtualenv/ramabit/3.7/lib/python3.7/site-packages/rest_framework/views.py", line 509, in dispatch
    response = self.handle_exception(exc)
  File "/home/ramabitc/virtualenv/ramabit/3.7/lib/python3.7/site-packages/rest_framework/views.py", line 469, in handle_exception
    self.raise_uncaught_exception(exc)
  File "/home/ramabitc/virtualenv/ramabit/3.7/lib/python3.7/site-packages/rest_framework/views.py", line 480, in raise_uncaught_exception
    raise exc
  File "/home/ramabitc/virtualenv/ramabit/3.7/lib/python3.7/site-packages/rest_framework/views.py", line 506, in dispatch
    response = handler(request, *args, **kwargs)
  File "/home/ramabitc/ramabit/api/views.py", line 40, in post
    user = User.objects.get(username = request.data['username'])
KeyError: 'username'
Internal Server Error: /api/v1/inv
Traceback (most recent call last):
  File "/home/ramabitc/virtualenv/ramabit/3.7/lib/python3.7/site-packages/django/core/handlers/exception.py", line 47, in inner
    response = get_response(request)
  File "/home/ramabitc/virtualenv/ramabit/3.7/lib/python3.7/site-packages/django/core/handlers/base.py", line 181, in _get_response
    response = wrapped_callback(request, *callback_args, **callback_kwargs)
  File "/home/ramabitc/virtualenv/ramabit/3.7/lib/python3.7/site-packages/django/views/decorators/csrf.py", line 54, in wrapped_view
    return view_func(*args, **kwargs)
  File "/home/ramabitc/virtualenv/ramabit/3.7/lib/python3.7/site-packages/django/views/generic/base.py", line 70, in view
    return self.dispatch(request, *args, **kwargs)
  File "/home/ramabitc/virtualenv/ramabit/3.7/lib/python3.7/site-packages/rest_framework/views.py", line 509, in dispatch
    response = self.handle_exception(exc)
  File "/home/ramabitc/virtualenv/ramabit/3.7/lib/python3.7/site-packages/rest_framework/views.py", line 469, in handle_exception
    self.raise_uncaught_exception(exc)
  File "/home/ramabitc/virtualenv/ramabit/3.7/lib/python3.7/site-packages/rest_framework/views.py", line 480, in raise_uncaught_exception
    raise exc
  File "/home/ramabitc/virtualenv/ramabit/3.7/lib/python3.7/site-packages/rest_framework/views.py", line 506, in dispatch
    response = handler(request, *args, **kwargs)
  File "/home/ramabitc/ramabit/api/views.py", line 40, in post
    user = User.objects.get(username = request.data['username'])
KeyError: 'username'
Internal Server Error: /api/v1/inv
Traceback (most recent call last):
  File "/home/ramabitc/virtualenv/ramabit/3.7/lib/python3.7/site-packages/django/core/handlers/exception.py", line 47, in inner
    response = get_response(request)
  File "/home/ramabitc/virtualenv/ramabit/3.7/lib/python3.7/site-packages/django/core/handlers/base.py", line 181, in _get_response
    response = wrapped_callback(request, *callback_args, **callback_kwargs)
  File "/home/ramabitc/virtualenv/ramabit/3.7/lib/python3.7/site-packages/django/views/decorators/csrf.py", line 54, in wrapped_view
    return view_func(*args, **kwargs)
  File "/home/ramabitc/virtualenv/ramabit/3.7/lib/python3.7/site-packages/django/views/generic/base.py", line 70, in view
    return self.dispatch(request, *args, **kwargs)
  File "/home/ramabitc/virtualenv/ramabit/3.7/lib/python3.7/site-packages/rest_framework/views.py", line 509, in dispatch
    response = self.handle_exception(exc)
  File "/home/ramabitc/virtualenv/ramabit/3.7/lib/python3.7/site-packages/rest_framework/views.py", line 469, in handle_exception
    self.raise_uncaught_exception(exc)
  File "/home/ramabitc/virtualenv/ramabit/3.7/lib/python3.7/site-packages/rest_framework/views.py", line 480, in raise_uncaught_exception
    raise exc
  File "/home/ramabitc/virtualenv/ramabit/3.7/lib/python3.7/site-packages/rest_framework/views.py", line 506, in dispatch
    response = handler(request, *args, **kwargs)
  File "/home/ramabitc/ramabit/api/views.py", line 40, in post
    user = User.objects.get(username = request.data['username'])
KeyError: 'username'
Internal Server Error: /api/v1/inv
Traceback (most recent call last):
  File "/home/ramabitc/virtualenv/ramabit/3.7/lib/python3.7/site-packages/django/core/handlers/exception.py", line 47, in inner
    response = get_response(request)
  File "/home/ramabitc/virtualenv/ramabit/3.7/lib/python3.7/site-packages/django/core/handlers/base.py", line 181, in _get_response
    response = wrapped_callback(request, *callback_args, **callback_kwargs)
  File "/home/ramabitc/virtualenv/ramabit/3.7/lib/python3.7/site-packages/django/views/decorators/csrf.py", line 54, in wrapped_view
    return view_func(*args, **kwargs)
  File "/home/ramabitc/virtualenv/ramabit/3.7/lib/python3.7/site-packages/django/views/generic/base.py", line 70, in view
    return self.dispatch(request, *args, **kwargs)
  File "/home/ramabitc/virtualenv/ramabit/3.7/lib/python3.7/site-packages/rest_framework/views.py", line 509, in dispatch
    response = self.handle_exception(exc)
  File "/home/ramabitc/virtualenv/ramabit/3.7/lib/python3.7/site-packages/rest_framework/views.py", line 469, in handle_exception
    self.raise_uncaught_exception(exc)
  File "/home/ramabitc/virtualenv/ramabit/3.7/lib/python3.7/site-packages/rest_framework/views.py", line 480, in raise_uncaught_exception
    raise exc
  File "/home/ramabitc/virtualenv/ramabit/3.7/lib/python3.7/site-packages/rest_framework/views.py", line 506, in dispatch
    response = handler(request, *args, **kwargs)
  File "/home/ramabitc/ramabit/api/views.py", line 40, in post
    user = User.objects.get(username = request.data['username'])
KeyError: 'username'
Internal Server Error: /api/v1/inv
Traceback (most recent call last):
  File "/home/ramabitc/virtualenv/ramabit/3.7/lib/python3.7/site-packages/django/core/handlers/exception.py", line 47, in inner
    response = get_response(request)
  File "/home/ramabitc/virtualenv/ramabit/3.7/lib/python3.7/site-packages/django/core/handlers/base.py", line 181, in _get_response
    response = wrapped_callback(request, *callback_args, **callback_kwargs)
  File "/home/ramabitc/virtualenv/ramabit/3.7/lib/python3.7/site-packages/django/views/decorators/csrf.py", line 54, in wrapped_view
    return view_func(*args, **kwargs)
  File "/home/ramabitc/virtualenv/ramabit/3.7/lib/python3.7/site-packages/django/views/generic/base.py", line 70, in view
    return self.dispatch(request, *args, **kwargs)
  File "/home/ramabitc/virtualenv/ramabit/3.7/lib/python3.7/site-packages/rest_framework/views.py", line 509, in dispatch
    response = self.handle_exception(exc)
  File "/home/ramabitc/virtualenv/ramabit/3.7/lib/python3.7/site-packages/rest_framework/views.py", line 469, in handle_exception
    self.raise_uncaught_exception(exc)
  File "/home/ramabitc/virtualenv/ramabit/3.7/lib/python3.7/site-packages/rest_framework/views.py", line 480, in raise_uncaught_exception
    raise exc
  File "/home/ramabitc/virtualenv/ramabit/3.7/lib/python3.7/site-packages/rest_framework/views.py", line 506, in dispatch
    response = handler(request, *args, **kwargs)
  File "/home/ramabitc/ramabit/api/views.py", line 40, in post
    user = User.objects.get(username = request.data['username'])
KeyError: 'username'
Internal Server Error: /api/v1/inv
Traceback (most recent call last):
  File "/home/ramabitc/virtualenv/ramabit/3.7/lib/python3.7/site-packages/django/core/handlers/exception.py", line 47, in inner
    response = get_response(request)
  File "/home/ramabitc/virtualenv/ramabit/3.7/lib/python3.7/site-packages/django/core/handlers/base.py", line 181, in _get_response
    response = wrapped_callback(request, *callback_args, **callback_kwargs)
  File "/home/ramabitc/virtualenv/ramabit/3.7/lib/python3.7/site-packages/django/views/decorators/csrf.py", line 54, in wrapped_view
    return view_func(*args, **kwargs)
  File "/home/ramabitc/virtualenv/ramabit/3.7/lib/python3.7/site-packages/django/views/generic/base.py", line 70, in view
    return self.dispatch(request, *args, **kwargs)
  File "/home/ramabitc/virtualenv/ramabit/3.7/lib/python3.7/site-packages/rest_framework/views.py", line 509, in dispatch
    response = self.handle_exception(exc)
  File "/home/ramabitc/virtualenv/ramabit/3.7/lib/python3.7/site-packages/rest_framework/views.py", line 469, in handle_exception
    self.raise_uncaught_exception(exc)
  File "/home/ramabitc/virtualenv/ramabit/3.7/lib/python3.7/site-packages/rest_framework/views.py", line 480, in raise_uncaught_exception
    raise exc
  File "/home/ramabitc/virtualenv/ramabit/3.7/lib/python3.7/site-packages/rest_framework/views.py", line 506, in dispatch
    response = handler(request, *args, **kwargs)
  File "/home/ramabitc/ramabit/api/views.py", line 40, in post
    user = User.objects.get(username = request.data['username'])
KeyError: 'username'
Internal Server Error: /api/v1/inv
Traceback (most recent call last):
  File "/home/ramabitc/virtualenv/ramabit/3.7/lib/python3.7/site-packages/django/core/handlers/exception.py", line 47, in inner
    response = get_response(request)
  File "/home/ramabitc/virtualenv/ramabit/3.7/lib/python3.7/site-packages/django/core/handlers/base.py", line 181, in _get_response
    response = wrapped_callback(request, *callback_args, **callback_kwargs)
  File "/home/ramabitc/virtualenv/ramabit/3.7/lib/python3.7/site-packages/django/views/decorators/csrf.py", line 54, in wrapped_view
    return view_func(*args, **kwargs)
  File "/home/ramabitc/virtualenv/ramabit/3.7/lib/python3.7/site-packages/django/views/generic/base.py", line 70, in view
    return self.dispatch(request, *args, **kwargs)
  File "/home/ramabitc/virtualenv/ramabit/3.7/lib/python3.7/site-packages/rest_framework/views.py", line 509, in dispatch
    response = self.handle_exception(exc)
  File "/home/ramabitc/virtualenv/ramabit/3.7/lib/python3.7/site-packages/rest_framework/views.py", line 469, in handle_exception
    self.raise_uncaught_exception(exc)
  File "/home/ramabitc/virtualenv/ramabit/3.7/lib/python3.7/site-packages/rest_framework/views.py", line 480, in raise_uncaught_exception
    raise exc
  File "/home/ramabitc/virtualenv/ramabit/3.7/lib/python3.7/site-packages/rest_framework/views.py", line 506, in dispatch
    response = handler(request, *args, **kwargs)
  File "/home/ramabitc/ramabit/api/views.py", line 40, in post
    user = User.objects.get(username = request.data['username'])
KeyError: 'username'
Internal Server Error: /api/v1/inv
Traceback (most recent call last):
  File "/home/ramabitc/virtualenv/ramabit/3.7/lib/python3.7/site-packages/django/core/handlers/exception.py", line 47, in inner
    response = get_response(request)
  File "/home/ramabitc/virtualenv/ramabit/3.7/lib/python3.7/site-packages/django/core/handlers/base.py", line 181, in _get_response
    response = wrapped_callback(request, *callback_args, **callback_kwargs)
  File "/home/ramabitc/virtualenv/ramabit/3.7/lib/python3.7/site-packages/django/views/decorators/csrf.py", line 54, in wrapped_view
    return view_func(*args, **kwargs)
  File "/home/ramabitc/virtualenv/ramabit/3.7/lib/python3.7/site-packages/django/views/generic/base.py", line 70, in view
    return self.dispatch(request, *args, **kwargs)
  File "/home/ramabitc/virtualenv/ramabit/3.7/lib/python3.7/site-packages/rest_framework/views.py", line 509, in dispatch
    response = self.handle_exception(exc)
  File "/home/ramabitc/virtualenv/ramabit/3.7/lib/python3.7/site-packages/rest_framework/views.py", line 469, in handle_exception
    self.raise_uncaught_exception(exc)
  File "/home/ramabitc/virtualenv/ramabit/3.7/lib/python3.7/site-packages/rest_framework/views.py", line 480, in raise_uncaught_exception
    raise exc
  File "/home/ramabitc/virtualenv/ramabit/3.7/lib/python3.7/site-packages/rest_framework/views.py", line 506, in dispatch
    response = handler(request, *args, **kwargs)
  File "/home/ramabitc/ramabit/api/views.py", line 40, in post
    user = User.objects.get(username = request.data['username'])
KeyError: 'username'
Internal Server Error: /api/v1/inv
Traceback (most recent call last):
  File "/home/ramabitc/virtualenv/ramabit/3.7/lib/python3.7/site-packages/django/core/handlers/exception.py", line 47, in inner
    response = get_response(request)
  File "/home/ramabitc/virtualenv/ramabit/3.7/lib/python3.7/site-packages/django/core/handlers/base.py", line 181, in _get_response
    response = wrapped_callback(request, *callback_args, **callback_kwargs)
  File "/home/ramabitc/virtualenv/ramabit/3.7/lib/python3.7/site-packages/django/views/decorators/csrf.py", line 54, in wrapped_view
    return view_func(*args, **kwargs)
  File "/home/ramabitc/virtualenv/ramabit/3.7/lib/python3.7/site-packages/django/views/generic/base.py", line 70, in view
    return self.dispatch(request, *args, **kwargs)
  File "/home/ramabitc/virtualenv/ramabit/3.7/lib/python3.7/site-packages/rest_framework/views.py", line 509, in dispatch
    response = self.handle_exception(exc)
  File "/home/ramabitc/virtualenv/ramabit/3.7/lib/python3.7/site-packages/rest_framework/views.py", line 469, in handle_exception
    self.raise_uncaught_exception(exc)
  File "/home/ramabitc/virtualenv/ramabit/3.7/lib/python3.7/site-packages/rest_framework/views.py", line 480, in raise_uncaught_exception
    raise exc
  File "/home/ramabitc/virtualenv/ramabit/3.7/lib/python3.7/site-packages/rest_framework/views.py", line 506, in dispatch
    response = handler(request, *args, **kwargs)
  File "/home/ramabitc/ramabit/api/views.py", line 40, in post
    user = User.objects.get(username = request.data['username'])
KeyError: 'username'
Internal Server Error: /api/v1/inv
Traceback (most recent call last):
  File "/home/ramabitc/virtualenv/ramabit/3.7/lib/python3.7/site-packages/django/core/handlers/exception.py", line 47, in inner
    response = get_response(request)
  File "/home/ramabitc/virtualenv/ramabit/3.7/lib/python3.7/site-packages/django/core/handlers/base.py", line 181, in _get_response
    response = wrapped_callback(request, *callback_args, **callback_kwargs)
  File "/home/ramabitc/virtualenv/ramabit/3.7/lib/python3.7/site-packages/django/views/decorators/csrf.py", line 54, in wrapped_view
    return view_func(*args, **kwargs)
  File "/home/ramabitc/virtualenv/ramabit/3.7/lib/python3.7/site-packages/django/views/generic/base.py", line 70, in view
    return self.dispatch(request, *args, **kwargs)
  File "/home/ramabitc/virtualenv/ramabit/3.7/lib/python3.7/site-packages/rest_framework/views.py", line 509, in dispatch
    response = self.handle_exception(exc)
  File "/home/ramabitc/virtualenv/ramabit/3.7/lib/python3.7/site-packages/rest_framework/views.py", line 469, in handle_exception
    self.raise_uncaught_exception(exc)
  File "/home/ramabitc/virtualenv/ramabit/3.7/lib/python3.7/site-packages/rest_framework/views.py", line 480, in raise_uncaught_exception
    raise exc
  File "/home/ramabitc/virtualenv/ramabit/3.7/lib/python3.7/site-packages/rest_framework/views.py", line 506, in dispatch
    response = handler(request, *args, **kwargs)
  File "/home/ramabitc/ramabit/api/views.py", line 40, in post
    user = User.objects.get(username = request.data['username'])
KeyError: 'username'
Internal Server Error: /api/v1/inv
Traceback (most recent call last):
  File "/home/ramabitc/virtualenv/ramabit/3.7/lib/python3.7/site-packages/django/core/handlers/exception.py", line 47, in inner
    response = get_response(request)
  File "/home/ramabitc/virtualenv/ramabit/3.7/lib/python3.7/site-packages/django/core/handlers/base.py", line 181, in _get_response
    response = wrapped_callback(request, *callback_args, **callback_kwargs)
  File "/home/ramabitc/virtualenv/ramabit/3.7/lib/python3.7/site-packages/django/views/decorators/csrf.py", line 54, in wrapped_view
    return view_func(*args, **kwargs)
  File "/home/ramabitc/virtualenv/ramabit/3.7/lib/python3.7/site-packages/django/views/generic/base.py", line 70, in view
    return self.dispatch(request, *args, **kwargs)
  File "/home/ramabitc/virtualenv/ramabit/3.7/lib/python3.7/site-packages/rest_framework/views.py", line 509, in dispatch
    response = self.handle_exception(exc)
  File "/home/ramabitc/virtualenv/ramabit/3.7/lib/python3.7/site-packages/rest_framework/views.py", line 469, in handle_exception
    self.raise_uncaught_exception(exc)
  File "/home/ramabitc/virtualenv/ramabit/3.7/lib/python3.7/site-packages/rest_framework/views.py", line 480, in raise_uncaught_exception
    raise exc
  File "/home/ramabitc/virtualenv/ramabit/3.7/lib/python3.7/site-packages/rest_framework/views.py", line 506, in dispatch
    response = handler(request, *args, **kwargs)
  File "/home/ramabitc/ramabit/api/views.py", line 40, in post
    user = User.objects.get(username = request.data['username'])
KeyError: 'username'
Internal Server Error: /api/v1/inv
Traceback (most recent call last):
  File "/home/ramabitc/virtualenv/ramabit/3.7/lib/python3.7/site-packages/django/core/handlers/exception.py", line 47, in inner
    response = get_response(request)
  File "/home/ramabitc/virtualenv/ramabit/3.7/lib/python3.7/site-packages/django/core/handlers/base.py", line 181, in _get_response
    response = wrapped_callback(request, *callback_args, **callback_kwargs)
  File "/home/ramabitc/virtualenv/ramabit/3.7/lib/python3.7/site-packages/django/views/decorators/csrf.py", line 54, in wrapped_view
    return view_func(*args, **kwargs)
  File "/home/ramabitc/virtualenv/ramabit/3.7/lib/python3.7/site-packages/django/views/generic/base.py", line 70, in view
    return self.dispatch(request, *args, **kwargs)
  File "/home/ramabitc/virtualenv/ramabit/3.7/lib/python3.7/site-packages/rest_framework/views.py", line 509, in dispatch
    response = self.handle_exception(exc)
  File "/home/ramabitc/virtualenv/ramabit/3.7/lib/python3.7/site-packages/rest_framework/views.py", line 469, in handle_exception
    self.raise_uncaught_exception(exc)
  File "/home/ramabitc/virtualenv/ramabit/3.7/lib/python3.7/site-packages/rest_framework/views.py", line 480, in raise_uncaught_exception
    raise exc
  File "/home/ramabitc/virtualenv/ramabit/3.7/lib/python3.7/site-packages/rest_framework/views.py", line 506, in dispatch
    response = handler(request, *args, **kwargs)
  File "/home/ramabitc/ramabit/api/views.py", line 40, in post
    user = User.objects.get(username = request.data['username'])
KeyError: 'username'
Internal Server Error: /api/v1/inv
Traceback (most recent call last):
  File "/home/ramabitc/virtualenv/ramabit/3.7/lib/python3.7/site-packages/django/core/handlers/exception.py", line 47, in inner
    response = get_response(request)
  File "/home/ramabitc/virtualenv/ramabit/3.7/lib/python3.7/site-packages/django/core/handlers/base.py", line 181, in _get_response
    response = wrapped_callback(request, *callback_args, **callback_kwargs)
  File "/home/ramabitc/virtualenv/ramabit/3.7/lib/python3.7/site-packages/django/views/decorators/csrf.py", line 54, in wrapped_view
    return view_func(*args, **kwargs)
  File "/home/ramabitc/virtualenv/ramabit/3.7/lib/python3.7/site-packages/django/views/generic/base.py", line 70, in view
    return self.dispatch(request, *args, **kwargs)
  File "/home/ramabitc/virtualenv/ramabit/3.7/lib/python3.7/site-packages/rest_framework/views.py", line 509, in dispatch
    response = self.handle_exception(exc)
  File "/home/ramabitc/virtualenv/ramabit/3.7/lib/python3.7/site-packages/rest_framework/views.py", line 469, in handle_exception
    self.raise_uncaught_exception(exc)
  File "/home/ramabitc/virtualenv/ramabit/3.7/lib/python3.7/site-packages/rest_framework/views.py", line 480, in raise_uncaught_exception
    raise exc
  File "/home/ramabitc/virtualenv/ramabit/3.7/lib/python3.7/site-packages/rest_framework/views.py", line 506, in dispatch
    response = handler(request, *args, **kwargs)
  File "/home/ramabitc/ramabit/api/views.py", line 40, in post
    user = User.objects.get(username = request.data['username'])
KeyError: 'username'
